Workbook
Name BASE: MISCELANEOS!$1:$1048576
Name BASE: 'LISTADO GENERAL '!$1:$1048576
Name consig: #REF!
Name CONSIGNACION: #REF!
Name mm: #REF!
Name STK: STK!$1:$1048576
Name UNIPHARMA: #REF!

Sheet PEDIDO
G6: LISTADO GENERAL
A7: =TODAY() -> 45730 | B7: TIPO ALMACEN | D7: P.P | E7: =IFERROR((H10/G10),0) -> 0 | F7: PEDIDO
A8: CLIENTE: | F8: ZONA:
A9: RIF: | D9: VENDEDOR:
A10: CONDICION DE PAGO: | D10: =+'LISTADO GENERAL '!V13 -> 45733 | F10: TOTAL UNIDADES | G10: =SUM(F12:F1214) -> 0 | H10: =SUM(H12:H1515) -> 0
A11: COD | C11: DESCRIPCION | D11: VENCE | E11: LAB | F11: CANT | G11: PRECIO | H11: SUB-TOTAL
A12: {=IFERROR(INDEX('REF1'!B:K,SMALL('REF1'!K:K,ROW()-11),1),"")} | B12: {=IFERROR(INDEX('REF1'!B:K,SMALL('REF1'!K:K,ROW()-11),3),"")} | C12: {=IFERROR(INDEX('REF1'!B:K,SMALL('REF1'!K:K,ROW()-11),2),"")} | D12: {=IFERROR(INDEX('REF1'!B:K,SMALL('REF1'!K:K,ROW()-11),5),"")} | E12: {=IFERROR(INDEX('REF1'!B:K,SMALL('REF1'!K:K,ROW()-11),4),"")} | F12: {=IFERROR(INDEX('REF1'!B:K,SMALL('REF1'!K:K,ROW()-11),6),"")} | G12: {=IFERROR(INDEX('REF1'!B:K,SMALL('REF1'!K:K,ROW()-11),7),"")} | H12: {=IFERROR(INDEX('REF1'!B:K,SMALL('REF1'!K:K,ROW()-11),8),"")} | I12: =IFERROR(_xlfn.XLOOKUP(A12,'LISTADO GENERAL '!B14:B2208,'LISTADO GENERAL '!A14:A2208),"")
A13: {=IFERROR(INDEX('REF1'!B:K,SMALL('REF1'!K:K,ROW()-11),1),"")} | B13: {=IFERROR(INDEX('REF1'!B:K,SMALL('REF1'!K:K,ROW()-11),3),"")} | C13: {=IFERROR(INDEX('REF1'!B:K,SMALL('REF1'!K:K,ROW()-11),2),"")} | D13: {=IFERROR(INDEX('REF1'!B:K,SMALL('REF1'!K:K,ROW()-11),5),"")} | E13: {=IFERROR(INDEX('REF1'!B:K,SMALL('REF1'!K:K,ROW()-11),4),"")} | F13: {=IFERROR(INDEX('REF1'!B:K,SMALL('REF1'!K:K,ROW()-11),6),"")} | G13: {=IFERROR(INDEX('REF1'!B:K,SMALL('REF1'!K:K,ROW()-11),7),"")} | H13: {=IFERROR(INDEX('REF1'!B:K,SMALL('REF1'!K:K,ROW()-11),8),"")} | I13: =IFERROR(_xlfn.XLOOKUP(A13,'LISTADO GENERAL '!B15:B2208,'LISTADO GENERAL '!A15:A2208),"")
A14: {=IFERROR(INDEX('REF1'!B:K,SMALL('REF1'!K:K,ROW()-11),1),"")} | B14: {=IFERROR(INDEX('REF1'!B:K,SMALL('REF1'!K:K,ROW()-11),3),"")} | C14: {=IFERROR(INDEX('REF1'!B:K,SMALL('REF1'!K:K,ROW()-11),2),"")} | D14: {=IFERROR(INDEX('REF1'!B:K,SMALL('REF1'!K:K,ROW()-11),5),"")} | E14: {=IFERROR(INDEX('REF1'!B:K,SMALL('REF1'!K:K,ROW()-11),4),"")} | F14: {=IFERROR(INDEX('REF1'!B:K,SMALL('REF1'!K:K,ROW()-11),6),"")} | G14: {=IFERROR(INDEX('REF1'!B:K,SMALL('REF1'!K:K,ROW()-11),7),"")} | H14: {=IFERROR(INDEX('REF1'!B:K,SMALL('REF1'!K:K,ROW()-11),8),"")} | I14: =IFERROR(_xlfn.XLOOKUP(A14,'LISTADO GENERAL '!B16:B2208,'LISTADO GENERAL '!A16:A2208),"")
A15: {=IFERROR(INDEX('REF1'!B:K,SMALL('REF1'!K:K,ROW()-11),1),"")} | B15: {=IFERROR(INDEX('REF1'!B:K,SMALL('REF1'!K:K,ROW()-11),3),"")} | C15: {=IFERROR(INDEX('REF1'!B:K,SMALL('REF1'!K:K,ROW()-11),2),"")} | D15: {=IFERROR(INDEX('REF1'!B:K,SMALL('REF1'!K:K,ROW()-11),5),"")} | E15: {=IFERROR(INDEX('REF1'!B:K,SMALL('REF1'!K:K,ROW()-11),4),"")} | F15: {=IFERROR(INDEX('REF1'!B:K,SMALL('REF1'!K:K,ROW()-11),6),"")} | G15: {=IFERROR(INDEX('REF1'!B:K,SMALL('REF1'!K:K,ROW()-11),7),"")} | H15: {=IFERROR(INDEX('REF1'!B:K,SMALL('REF1'!K:K,ROW()-11),8),"")} | I15: =IFERROR(_xlfn.XLOOKUP(A15,'LISTADO GENERAL '!B17:B2208,'LISTADO GENERAL '!A17:A2208),"")
A16: {=IFERROR(INDEX('REF1'!B:K,SMALL('REF1'!K:K,ROW()-11),1),"")} | B16: {=IFERROR(INDEX('REF1'!B:K,SMALL('REF1'!K:K,ROW()-11),3),"")} | C16: {=IFERROR(INDEX('REF1'!B:K,SMALL('REF1'!K:K,ROW()-11),2),"")} | D16: {=IFERROR(INDEX('REF1'!B:K,SMALL('REF1'!K:K,ROW()-11),5),"")} | E16: {=IFERROR(INDEX('REF1'!B:K,SMALL('REF1'!K:K,ROW()-11),4),"")} | F16: {=IFERROR(INDEX('REF1'!B:K,SMALL('REF1'!K:K,ROW()-11),6),"")} | G16: {=IFERROR(INDEX('REF1'!B:K,SMALL('REF1'!K:K,ROW()-11),7),"")} | H16: {=IFERROR(INDEX('REF1'!B:K,SMALL('REF1'!K:K,ROW()-11),8),"")} | I16: =IFERROR(_xlfn.XLOOKUP(A16,'LISTADO GENERAL '!B18:B2208,'LISTADO GENERAL '!A18:A2208),"")
A17: {=IFERROR(INDEX('REF1'!B:K,SMALL('REF1'!K:K,ROW()-11),1),"")} | B17: {=IFERROR(INDEX('REF1'!B:K,SMALL('REF1'!K:K,ROW()-11),3),"")} | C17: {=IFERROR(INDEX('REF1'!B:K,SMALL('REF1'!K:K,ROW()-11),2),"")} | D17: {=IFERROR(INDEX('REF1'!B:K,SMALL('REF1'!K:K,ROW()-11),5),"")} | E17: {=IFERROR(INDEX('REF1'!B:K,SMALL('REF1'!K:K,ROW()-11),4),"")} | F17: {=IFERROR(INDEX('REF1'!B:K,SMALL('REF1'!K:K,ROW()-11),6),"")} | G17: {=IFERROR(INDEX('REF1'!B:K,SMALL('REF1'!K:K,ROW()-11),7),"")} | H17: {=IFERROR(INDEX('REF1'!B:K,SMALL('REF1'!K:K,ROW()-11),8),"")} | I17: =IFERROR(_xlfn.XLOOKUP(A17,'LISTADO GENERAL '!B19:B2208,'LISTADO GENERAL '!A19:A2208),"")
A18: {=IFERROR(INDEX('REF1'!B:K,SMALL('REF1'!K:K,ROW()-11),1),"")} | B18: {=IFERROR(INDEX('REF1'!B:K,SMALL('REF1'!K:K,ROW()-11),3),"")} | C18: {=IFERROR(INDEX('REF1'!B:K,SMALL('REF1'!K:K,ROW()-11),2),"")} | D18: {=IFERROR(INDEX('REF1'!B:K,SMALL('REF1'!K:K,ROW()-11),5),"")} | E18: {=IFERROR(INDEX('REF1'!B:K,SMALL('REF1'!K:K,ROW()-11),4),"")} | F18: {=IFERROR(INDEX('REF1'!B:K,SMALL('REF1'!K:K,ROW()-11),6),"")} | G18: {=IFERROR(INDEX('REF1'!B:K,SMALL('REF1'!K:K,ROW()-11),7),"")} | H18: {=IFERROR(INDEX('REF1'!B:K,SMALL('REF1'!K:K,ROW()-11),8),"")} | I18: =IFERROR(_xlfn.XLOOKUP(A18,'LISTADO GENERAL '!B20:B2208,'LISTADO GENERAL '!A20:A2208),"")
A19: {=IFERROR(INDEX('REF1'!B:K,SMALL('REF1'!K:K,ROW()-11),1),"")} | B19: {=IFERROR(INDEX('REF1'!B:K,SMALL('REF1'!K:K,ROW()-11),3),"")} | C19: {=IFERROR(INDEX('REF1'!B:K,SMALL('REF1'!K:K,ROW()-11),2),"")} | D19: {=IFERROR(INDEX('REF1'!B:K,SMALL('REF1'!K:K,ROW()-11),5),"")} | E19: {=IFERROR(INDEX('REF1'!B:K,SMALL('REF1'!K:K,ROW()-11),4),"")} | F19: {=IFERROR(INDEX('REF1'!B:K,SMALL('REF1'!K:K,ROW()-11),6),"")} | G19: {=IFERROR(INDEX('REF1'!B:K,SMALL('REF1'!K:K,ROW()-11),7),"")} | H19: {=IFERROR(INDEX('REF1'!B:K,SMALL('REF1'!K:K,ROW()-11),8),"")} | I19: =IFERROR(_xlfn.XLOOKUP(A19,'LISTADO GENERAL '!B21:B2208,'LISTADO GENERAL '!A21:A2208),"")
A20: {=IFERROR(INDEX('REF1'!B:K,SMALL('REF1'!K:K,ROW()-11),1),"")} | B20: {=IFERROR(INDEX('REF1'!B:K,SMALL('REF1'!K:K,ROW()-11),3),"")} | C20: {=IFERROR(INDEX('REF1'!B:K,SMALL('REF1'!K:K,ROW()-11),2),"")} | D20: {=IFERROR(INDEX('REF1'!B:K,SMALL('REF1'!K:K,ROW()-11),5),"")} | E20: {=IFERROR(INDEX('REF1'!B:K,SMALL('REF1'!K:K,ROW()-11),4),"")} | F20: {=IFERROR(INDEX('REF1'!B:K,SMALL('REF1'!K:K,ROW()-11),6),"")} | G20: {=IFERROR(INDEX('REF1'!B:K,SMALL('REF1'!K:K,ROW()-11),7),"")} | H20: {=IFERROR(INDEX('REF1'!B:K,SMALL('REF1'!K:K,ROW()-11),8),"")} | I20: =IFERROR(_xlfn.XLOOKUP(A20,'LISTADO GENERAL '!B22:B2208,'LISTADO GENERAL '!A22:A2208),"")
A21: {=IFERROR(INDEX('REF1'!B:K,SMALL('REF1'!K:K,ROW()-11),1),"")} | B21: {=IFERROR(INDEX('REF1'!B:K,SMALL('REF1'!K:K,ROW()-11),3),"")} | C21: {=IFERROR(INDEX('REF1'!B:K,SMALL('REF1'!K:K,ROW()-11),2),"")} | D21: {=IFERROR(INDEX('REF1'!B:K,SMALL('REF1'!K:K,ROW()-11),5),"")} | E21: {=IFERROR(INDEX('REF1'!B:K,SMALL('REF1'!K:K,ROW()-11),4),"")} | F21: {=IFERROR(INDEX('REF1'!B:K,SMALL('REF1'!K:K,ROW()-11),6),"")} | G21: {=IFERROR(INDEX('REF1'!B:K,SMALL('REF1'!K:K,ROW()-11),7),"")} | H21: {=IFERROR(INDEX('REF1'!B:K,SMALL('REF1'!K:K,ROW()-11),8),"")} | I21: =IFERROR(_xlfn.XLOOKUP(A21,'LISTADO GENERAL '!B23:B2208,'LISTADO GENERAL '!A23:A2208),"")
A22: {=IFERROR(INDEX('REF1'!B:K,SMALL('REF1'!K:K,ROW()-11),1),"")} | B22: {=IFERROR(INDEX('REF1'!B:K,SMALL('REF1'!K:K,ROW()-11),3),"")} | C22: {=IFERROR(INDEX('REF1'!B:K,SMALL('REF1'!K:K,ROW()-11),2),"")} | D22: {=IFERROR(INDEX('REF1'!B:K,SMALL('REF1'!K:K,ROW()-11),5),"")} | E22: {=IFERROR(INDEX('REF1'!B:K,SMALL('REF1'!K:K,ROW()-11),4),"")} | F22: {=IFERROR(INDEX('REF1'!B:K,SMALL('REF1'!K:K,ROW()-11),6),"")} | G22: {=IFERROR(INDEX('REF1'!B:K,SMALL('REF1'!K:K,ROW()-11),7),"")} | H22: {=IFERROR(INDEX('REF1'!B:K,SMALL('REF1'!K:K,ROW()-11),8),"")} | I22: =IFERROR(_xlfn.XLOOKUP(A22,'LISTADO GENERAL '!B24:B2208,'LISTADO GENERAL '!A24:A2208),"")
A23: {=IFERROR(INDEX('REF1'!B:K,SMALL('REF1'!K:K,ROW()-11),1),"")} | B23: {=IFERROR(INDEX('REF1'!B:K,SMALL('REF1'!K:K,ROW()-11),3),"")} | C23: {=IFERROR(INDEX('REF1'!B:K,SMALL('REF1'!K:K,ROW()-11),2),"")} | D23: {=IFERROR(INDEX('REF1'!B:K,SMALL('REF1'!K:K,ROW()-11),5),"")} | E23: {=IFERROR(INDEX('REF1'!B:K,SMALL('REF1'!K:K,ROW()-11),4),"")} | F23: {=IFERROR(INDEX('REF1'!B:K,SMALL('REF1'!K:K,ROW()-11),6),"")} | G23: {=IFERROR(INDEX('REF1'!B:K,SMALL('REF1'!K:K,ROW()-11),7),"")} | H23: {=IFERROR(INDEX('REF1'!B:K,SMALL('REF1'!K:K,ROW()-11),8),"")} | I23: =IFERROR(_xlfn.XLOOKUP(A23,'LISTADO GENERAL '!B25:B2208,'LISTADO GENERAL '!A25:A2208),"")
A24: {=IFERROR(INDEX('REF1'!B:K,SMALL('REF1'!K:K,ROW()-11),1),"")} | B24: {=IFERROR(INDEX('REF1'!B:K,SMALL('REF1'!K:K,ROW()-11),3),"")} | C24: {=IFERROR(INDEX('REF1'!B:K,SMALL('REF1'!K:K,ROW()-11),2),"")} | D24: {=IFERROR(INDEX('REF1'!B:K,SMALL('REF1'!K:K,ROW()-11),5),"")} | E24: {=IFERROR(INDEX('REF1'!B:K,SMALL('REF1'!K:K,ROW()-11),4),"")} | F24: {=IFERROR(INDEX('REF1'!B:K,SMALL('REF1'!K:K,ROW()-11),6),"")} | G24: {=IFERROR(INDEX('REF1'!B:K,SMALL('REF1'!K:K,ROW()-11),7),"")} | H24: {=IFERROR(INDEX('REF1'!B:K,SMALL('REF1'!K:K,ROW()-11),8),"")} | I24: =IFERROR(_xlfn.XLOOKUP(A24,'LISTADO GENERAL '!B26:B2208,'LISTADO GENERAL '!A26:A2208),"")
A25: {=IFERROR(INDEX('REF1'!B:K,SMALL('REF1'!K:K,ROW()-11),1),"")} | B25: {=IFERROR(INDEX('REF1'!B:K,SMALL('REF1'!K:K,ROW()-11),3),"")} | C25: {=IFERROR(INDEX('REF1'!B:K,SMALL('REF1'!K:K,ROW()-11),2),"")} | D25: {=IFERROR(INDEX('REF1'!B:K,SMALL('REF1'!K:K,ROW()-11),5),"")} | E25: {=IFERROR(INDEX('REF1'!B:K,SMALL('REF1'!K:K,ROW()-11),4),"")} | F25: {=IFERROR(INDEX('REF1'!B:K,SMALL('REF1'!K:K,ROW()-11),6),"")} | G25: {=IFERROR(INDEX('REF1'!B:K,SMALL('REF1'!K:K,ROW()-11),7),"")} | H25: {=IFERROR(INDEX('REF1'!B:K,SMALL('REF1'!K:K,ROW()-11),8),"")} | I25: =IFERROR(_xlfn.XLOOKUP(A25,'LISTADO GENERAL '!B27:B2208,'LISTADO GENERAL '!A27:A2208),"")
A26: {=IFERROR(INDEX('REF1'!B:K,SMALL('REF1'!K:K,ROW()-11),1),"")} | B26: {=IFERROR(INDEX('REF1'!B:K,SMALL('REF1'!K:K,ROW()-11),3),"")} | C26: {=IFERROR(INDEX('REF1'!B:K,SMALL('REF1'!K:K,ROW()-11),2),"")} | D26: {=IFERROR(INDEX('REF1'!B:K,SMALL('REF1'!K:K,ROW()-11),5),"")} | E26: {=IFERROR(INDEX('REF1'!B:K,SMALL('REF1'!K:K,ROW()-11),4),"")} | F26: {=IFERROR(INDEX('REF1'!B:K,SMALL('REF1'!K:K,ROW()-11),6),"")} | G26: {=IFERROR(INDEX('REF1'!B:K,SMALL('REF1'!K:K,ROW()-11),7),"")} | H26: {=IFERROR(INDEX('REF1'!B:K,SMALL('REF1'!K:K,ROW()-11),8),"")} | I26: =IFERROR(_xlfn.XLOOKUP(A26,'LISTADO GENERAL '!B28:B2208,'LISTADO GENERAL '!A28:A2208),"")
A27: {=IFERROR(INDEX('REF1'!B:K,SMALL('REF1'!K:K,ROW()-11),1),"")} | B27: {=IFERROR(INDEX('REF1'!B:K,SMALL('REF1'!K:K,ROW()-11),3),"")} | C27: {=IFERROR(INDEX('REF1'!B:K,SMALL('REF1'!K:K,ROW()-11),2),"")} | D27: {=IFERROR(INDEX('REF1'!B:K,SMALL('REF1'!K:K,ROW()-11),5),"")} | E27: {=IFERROR(INDEX('REF1'!B:K,SMALL('REF1'!K:K,ROW()-11),4),"")} | F27: {=IFERROR(INDEX('REF1'!B:K,SMALL('REF1'!K:K,ROW()-11),6),"")} | G27: {=IFERROR(INDEX('REF1'!B:K,SMALL('REF1'!K:K,ROW()-11),7),"")} | H27: {=IFERROR(INDEX('REF1'!B:K,SMALL('REF1'!K:K,ROW()-11),8),"")} | I27: =IFERROR(_xlfn.XLOOKUP(A27,'LISTADO GENERAL '!B29:B2208,'LISTADO GENERAL '!A29:A2208),"")
A28: {=IFERROR(INDEX('REF1'!B:K,SMALL('REF1'!K:K,ROW()-11),1),"")} | B28: {=IFERROR(INDEX('REF1'!B:K,SMALL('REF1'!K:K,ROW()-11),3),"")} | C28: {=IFERROR(INDEX('REF1'!B:K,SMALL('REF1'!K:K,ROW()-11),2),"")} | D28: {=IFERROR(INDEX('REF1'!B:K,SMALL('REF1'!K:K,ROW()-11),5),"")} | E28: {=IFERROR(INDEX('REF1'!B:K,SMALL('REF1'!K:K,ROW()-11),4),"")} | F28: {=IFERROR(INDEX('REF1'!B:K,SMALL('REF1'!K:K,ROW()-11),6),"")} | G28: {=IFERROR(INDEX('REF1'!B:K,SMALL('REF1'!K:K,ROW()-11),7),"")} | H28: {=IFERROR(INDEX('REF1'!B:K,SMALL('REF1'!K:K,ROW()-11),8),"")} | I28: =IFERROR(_xlfn.XLOOKUP(A28,'LISTADO GENERAL '!B30:B2208,'LISTADO GENERAL '!A30:A2208),"")
A29: {=IFERROR(INDEX('REF1'!B:K,SMALL('REF1'!K:K,ROW()-11),1),"")} | B29: {=IFERROR(INDEX('REF1'!B:K,SMALL('REF1'!K:K,ROW()-11),3),"")} | C29: {=IFERROR(INDEX('REF1'!B:K,SMALL('REF1'!K:K,ROW()-11),2),"")} | D29: {=IFERROR(INDEX('REF1'!B:K,SMALL('REF1'!K:K,ROW()-11),5),"")} | E29: {=IFERROR(INDEX('REF1'!B:K,SMALL('REF1'!K:K,ROW()-11),4),"")} | F29: {=IFERROR(INDEX('REF1'!B:K,SMALL('REF1'!K:K,ROW()-11),6),"")} | G29: {=IFERROR(INDEX('REF1'!B:K,SMALL('REF1'!K:K,ROW()-11),7),"")} | H29: {=IFERROR(INDEX('REF1'!B:K,SMALL('REF1'!K:K,ROW()-11),8),"")} | I29: =IFERROR(_xlfn.XLOOKUP(A29,'LISTADO GENERAL '!B31:B2208,'LISTADO GENERAL '!A31:A2208),"")
A30: {=IFERROR(INDEX('REF1'!B:K,SMALL('REF1'!K:K,ROW()-11),1),"")} | B30: {=IFERROR(INDEX('REF1'!B:K,SMALL('REF1'!K:K,ROW()-11),3),"")} | C30: {=IFERROR(INDEX('REF1'!B:K,SMALL('REF1'!K:K,ROW()-11),2),"")} | D30: {=IFERROR(INDEX('REF1'!B:K,SMALL('REF1'!K:K,ROW()-11),5),"")} | E30: {=IFERROR(INDEX('REF1'!B:K,SMALL('REF1'!K:K,ROW()-11),4),"")} | F30: {=IFERROR(INDEX('REF1'!B:K,SMALL('REF1'!K:K,ROW()-11),6),"")} | G30: {=IFERROR(INDEX('REF1'!B:K,SMALL('REF1'!K:K,ROW()-11),7),"")} | H30: {=IFERROR(INDEX('REF1'!B:K,SMALL('REF1'!K:K,ROW()-11),8),"")} | I30: =IFERROR(_xlfn.XLOOKUP(A30,'LISTADO GENERAL '!B32:B2208,'LISTADO GENERAL '!A32:A2208),"")
A31: {=IFERROR(INDEX('REF1'!B:K,SMALL('REF1'!K:K,ROW()-11),1),"")} | B31: {=IFERROR(INDEX('REF1'!B:K,SMALL('REF1'!K:K,ROW()-11),3),"")} | C31: {=IFERROR(INDEX('REF1'!B:K,SMALL('REF1'!K:K,ROW()-11),2),"")} | D31: {=IFERROR(INDEX('REF1'!B:K,SMALL('REF1'!K:K,ROW()-11),5),"")} | E31: {=IFERROR(INDEX('REF1'!B:K,SMALL('REF1'!K:K,ROW()-11),4),"")} | F31: {=IFERROR(INDEX('REF1'!B:K,SMALL('REF1'!K:K,ROW()-11),6),"")} | G31: {=IFERROR(INDEX('REF1'!B:K,SMALL('REF1'!K:K,ROW()-11),7),"")} | H31: {=IFERROR(INDEX('REF1'!B:K,SMALL('REF1'!K:K,ROW()-11),8),"")} | I31: =IFERROR(_xlfn.XLOOKUP(A31,'LISTADO GENERAL '!B33:B2208,'LISTADO GENERAL '!A33:A2208),"")
A32: {=IFERROR(INDEX('REF1'!B:K,SMALL('REF1'!K:K,ROW()-11),1),"")} | B32: {=IFERROR(INDEX('REF1'!B:K,SMALL('REF1'!K:K,ROW()-11),3),"")} | C32: {=IFERROR(INDEX('REF1'!B:K,SMALL('REF1'!K:K,ROW()-11),2),"")} | D32: {=IFERROR(INDEX('REF1'!B:K,SMALL('REF1'!K:K,ROW()-11),5),"")} | E32: {=IFERROR(INDEX('REF1'!B:K,SMALL('REF1'!K:K,ROW()-11),4),"")} | F32: {=IFERROR(INDEX('REF1'!B:K,SMALL('REF1'!K:K,ROW()-11),6),"")} | G32: {=IFERROR(INDEX('REF1'!B:K,SMALL('REF1'!K:K,ROW()-11),7),"")} | H32: {=IFERROR(INDEX('REF1'!B:K,SMALL('REF1'!K:K,ROW()-11),8),"")} | I32: =IFERROR(_xlfn.XLOOKUP(A32,'LISTADO GENERAL '!B34:B2208,'LISTADO GENERAL '!A34:A2208),"")
A33: {=IFERROR(INDEX('REF1'!B:K,SMALL('REF1'!K:K,ROW()-11),1),"")} | B33: {=IFERROR(INDEX('REF1'!B:K,SMALL('REF1'!K:K,ROW()-11),3),"")} | C33: {=IFERROR(INDEX('REF1'!B:K,SMALL('REF1'!K:K,ROW()-11),2),"")} | D33: {=IFERROR(INDEX('REF1'!B:K,SMALL('REF1'!K:K,ROW()-11),5),"")} | E33: {=IFERROR(INDEX('REF1'!B:K,SMALL('REF1'!K:K,ROW()-11),4),"")} | F33: {=IFERROR(INDEX('REF1'!B:K,SMALL('REF1'!K:K,ROW()-11),6),"")} | G33: {=IFERROR(INDEX('REF1'!B:K,SMALL('REF1'!K:K,ROW()-11),7),"")} | H33: {=IFERROR(INDEX('REF1'!B:K,SMALL('REF1'!K:K,ROW()-11),8),"")} | I33: =IFERROR(_xlfn.XLOOKUP(A33,'LISTADO GENERAL '!B35:B2208,'LISTADO GENERAL '!A35:A2208),"")
A34: {=IFERROR(INDEX('REF1'!B:K,SMALL('REF1'!K:K,ROW()-11),1),"")} | B34: {=IFERROR(INDEX('REF1'!B:K,SMALL('REF1'!K:K,ROW()-11),3),"")} | C34: {=IFERROR(INDEX('REF1'!B:K,SMALL('REF1'!K:K,ROW()-11),2),"")} | D34: {=IFERROR(INDEX('REF1'!B:K,SMALL('REF1'!K:K,ROW()-11),5),"")} | E34: {=IFERROR(INDEX('REF1'!B:K,SMALL('REF1'!K:K,ROW()-11),4),"")} | F34: {=IFERROR(INDEX('REF1'!B:K,SMALL('REF1'!K:K,ROW()-11),6),"")} | G34: {=IFERROR(INDEX('REF1'!B:K,SMALL('REF1'!K:K,ROW()-11),7),"")} | H34: {=IFERROR(INDEX('REF1'!B:K,SMALL('REF1'!K:K,ROW()-11),8),"")} | I34: =IFERROR(_xlfn.XLOOKUP(A34,'LISTADO GENERAL '!B36:B2208,'LISTADO GENERAL '!A36:A2208),"")
A35: {=IFERROR(INDEX('REF1'!B:K,SMALL('REF1'!K:K,ROW()-11),1),"")} | B35: {=IFERROR(INDEX('REF1'!B:K,SMALL('REF1'!K:K,ROW()-11),3),"")} | C35: {=IFERROR(INDEX('REF1'!B:K,SMALL('REF1'!K:K,ROW()-11),2),"")} | D35: {=IFERROR(INDEX('REF1'!B:K,SMALL('REF1'!K:K,ROW()-11),5),"")} | E35: {=IFERROR(INDEX('REF1'!B:K,SMALL('REF1'!K:K,ROW()-11),4),"")} | F35: {=IFERROR(INDEX('REF1'!B:K,SMALL('REF1'!K:K,ROW()-11),6),"")} | G35: {=IFERROR(INDEX('REF1'!B:K,SMALL('REF1'!K:K,ROW()-11),7),"")} | H35: {=IFERROR(INDEX('REF1'!B:K,SMALL('REF1'!K:K,ROW()-11),8),"")} | I35: =IFERROR(_xlfn.XLOOKUP(A35,'LISTADO GENERAL '!B37:B2208,'LISTADO GENERAL '!A37:A2208),"")
A36: {=IFERROR(INDEX('REF1'!B:K,SMALL('REF1'!K:K,ROW()-11),1),"")} | B36: {=IFERROR(INDEX('REF1'!B:K,SMALL('REF1'!K:K,ROW()-11),3),"")} | C36: {=IFERROR(INDEX('REF1'!B:K,SMALL('REF1'!K:K,ROW()-11),2),"")} | D36: {=IFERROR(INDEX('REF1'!B:K,SMALL('REF1'!K:K,ROW()-11),5),"")} | E36: {=IFERROR(INDEX('REF1'!B:K,SMALL('REF1'!K:K,ROW()-11),4),"")} | F36: {=IFERROR(INDEX('REF1'!B:K,SMALL('REF1'!K:K,ROW()-11),6),"")} | G36: {=IFERROR(INDEX('REF1'!B:K,SMALL('REF1'!K:K,ROW()-11),7),"")} | H36: {=IFERROR(INDEX('REF1'!B:K,SMALL('REF1'!K:K,ROW()-11),8),"")} | I36: =IFERROR(_xlfn.XLOOKUP(A36,'LISTADO GENERAL '!B38:B2208,'LISTADO GENERAL '!A38:A2208),"")
A37: {=IFERROR(INDEX('REF1'!B:K,SMALL('REF1'!K:K,ROW()-11),1),"")} | B37: {=IFERROR(INDEX('REF1'!B:K,SMALL('REF1'!K:K,ROW()-11),3),"")} | C37: {=IFERROR(INDEX('REF1'!B:K,SMALL('REF1'!K:K,ROW()-11),2),"")} | D37: {=IFERROR(INDEX('REF1'!B:K,SMALL('REF1'!K:K,ROW()-11),5),"")} | E37: {=IFERROR(INDEX('REF1'!B:K,SMALL('REF1'!K:K,ROW()-11),4),"")} | F37: {=IFERROR(INDEX('REF1'!B:K,SMALL('REF1'!K:K,ROW()-11),6),"")} | G37: {=IFERROR(INDEX('REF1'!B:K,SMALL('REF1'!K:K,ROW()-11),7),"")} | H37: {=IFERROR(INDEX('REF1'!B:K,SMALL('REF1'!K:K,ROW()-11),8),"")} | I37: =IFERROR(_xlfn.XLOOKUP(A37,'LISTADO GENERAL '!B39:B2208,'LISTADO GENERAL '!A39:A2208),"")
A38: {=IFERROR(INDEX('REF1'!B:K,SMALL('REF1'!K:K,ROW()-11),1),"")} | B38: {=IFERROR(INDEX('REF1'!B:K,SMALL('REF1'!K:K,ROW()-11),3),"")} | C38: {=IFERROR(INDEX('REF1'!B:K,SMALL('REF1'!K:K,ROW()-11),2),"")} | D38: {=IFERROR(INDEX('REF1'!B:K,SMALL('REF1'!K:K,ROW()-11),5),"")} | E38: {=IFERROR(INDEX('REF1'!B:K,SMALL('REF1'!K:K,ROW()-11),4),"")} | F38: {=IFERROR(INDEX('REF1'!B:K,SMALL('REF1'!K:K,ROW()-11),6),"")} | G38: {=IFERROR(INDEX('REF1'!B:K,SMALL('REF1'!K:K,ROW()-11),7),"")} | H38: {=IFERROR(INDEX('REF1'!B:K,SMALL('REF1'!K:K,ROW()-11),8),"")} | I38: =IFERROR(_xlfn.XLOOKUP(A38,'LISTADO GENERAL '!B40:B2208,'LISTADO GENERAL '!A40:A2208),"")
A39: {=IFERROR(INDEX('REF1'!B:K,SMALL('REF1'!K:K,ROW()-11),1),"")} | B39: {=IFERROR(INDEX('REF1'!B:K,SMALL('REF1'!K:K,ROW()-11),3),"")} | C39: {=IFERROR(INDEX('REF1'!B:K,SMALL('REF1'!K:K,ROW()-11),2),"")} | D39: {=IFERROR(INDEX('REF1'!B:K,SMALL('REF1'!K:K,ROW()-11),5),"")} | E39: {=IFERROR(INDEX('REF1'!B:K,SMALL('REF1'!K:K,ROW()-11),4),"")} | F39: {=IFERROR(INDEX('REF1'!B:K,SMALL('REF1'!K:K,ROW()-11),6),"")} | G39: {=IFERROR(INDEX('REF1'!B:K,SMALL('REF1'!K:K,ROW()-11),7),"")} | H39: {=IFERROR(INDEX('REF1'!B:K,SMALL('REF1'!K:K,ROW()-11),8),"")} | I39: =IFERROR(_xlfn.XLOOKUP(A39,'LISTADO GENERAL '!B41:B2208,'LISTADO GENERAL '!A41:A2208),"")
A40: {=IFERROR(INDEX('REF1'!B:K,SMALL('REF1'!K:K,ROW()-11),1),"")} | B40: {=IFERROR(INDEX('REF1'!B:K,SMALL('REF1'!K:K,ROW()-11),3),"")} | C40: {=IFERROR(INDEX('REF1'!B:K,SMALL('REF1'!K:K,ROW()-11),2),"")} | D40: {=IFERROR(INDEX('REF1'!B:K,SMALL('REF1'!K:K,ROW()-11),5),"")} | E40: {=IFERROR(INDEX('REF1'!B:K,SMALL('REF1'!K:K,ROW()-11),4),"")} | F40: {=IFERROR(INDEX('REF1'!B:K,SMALL('REF1'!K:K,ROW()-11),6),"")} | G40: {=IFERROR(INDEX('REF1'!B:K,SMALL('REF1'!K:K,ROW()-11),7),"")} | H40: {=IFERROR(INDEX('REF1'!B:K,SMALL('REF1'!K:K,ROW()-11),8),"")} | I40: =IFERROR(_xlfn.XLOOKUP(A40,'LISTADO GENERAL '!B42:B2208,'LISTADO GENERAL '!A42:A2208),"")
A41: {=IFERROR(INDEX('REF1'!B:K,SMALL('REF1'!K:K,ROW()-11),1),"")} | B41: {=IFERROR(INDEX('REF1'!B:K,SMALL('REF1'!K:K,ROW()-11),3),"")} | C41: {=IFERROR(INDEX('REF1'!B:K,SMALL('REF1'!K:K,ROW()-11),2),"")} | D41: {=IFERROR(INDEX('REF1'!B:K,SMALL('REF1'!K:K,ROW()-11),5),"")} | E41: {=IFERROR(INDEX('REF1'!B:K,SMALL('REF1'!K:K,ROW()-11),4),"")} | F41: {=IFERROR(INDEX('REF1'!B:K,SMALL('REF1'!K:K,ROW()-11),6),"")} | G41: {=IFERROR(INDEX('REF1'!B:K,SMALL('REF1'!K:K,ROW()-11),7),"")} | H41: {=IFERROR(INDEX('REF1'!B:K,SMALL('REF1'!K:K,ROW()-11),8),"")} | I41: =IFERROR(_xlfn.XLOOKUP(A41,'LISTADO GENERAL '!B43:B2208,'LISTADO GENERAL '!A43:A2208),"")
A42: {=IFERROR(INDEX('REF1'!B:K,SMALL('REF1'!K:K,ROW()-11),1),"")} | B42: {=IFERROR(INDEX('REF1'!B:K,SMALL('REF1'!K:K,ROW()-11),3),"")} | C42: {=IFERROR(INDEX('REF1'!B:K,SMALL('REF1'!K:K,ROW()-11),2),"")} | D42: {=IFERROR(INDEX('REF1'!B:K,SMALL('REF1'!K:K,ROW()-11),5),"")} | E42: {=IFERROR(INDEX('REF1'!B:K,SMALL('REF1'!K:K,ROW()-11),4),"")} | F42: {=IFERROR(INDEX('REF1'!B:K,SMALL('REF1'!K:K,ROW()-11),6),"")} | G42: {=IFERROR(INDEX('REF1'!B:K,SMALL('REF1'!K:K,ROW()-11),7),"")} | H42: {=IFERROR(INDEX('REF1'!B:K,SMALL('REF1'!K:K,ROW()-11),8),"")} | I42: =IFERROR(_xlfn.XLOOKUP(A42,'LISTADO GENERAL '!B44:B2208,'LISTADO GENERAL '!A44:A2208),"")
A43: {=IFERROR(INDEX('REF1'!B:K,SMALL('REF1'!K:K,ROW()-11),1),"")} | B43: {=IFERROR(INDEX('REF1'!B:K,SMALL('REF1'!K:K,ROW()-11),3),"")} | C43: {=IFERROR(INDEX('REF1'!B:K,SMALL('REF1'!K:K,ROW()-11),2),"")} | D43: {=IFERROR(INDEX('REF1'!B:K,SMALL('REF1'!K:K,ROW()-11),5),"")} | E43: {=IFERROR(INDEX('REF1'!B:K,SMALL('REF1'!K:K,ROW()-11),4),"")} | F43: {=IFERROR(INDEX('REF1'!B:K,SMALL('REF1'!K:K,ROW()-11),6),"")} | G43: {=IFERROR(INDEX('REF1'!B:K,SMALL('REF1'!K:K,ROW()-11),7),"")} | H43: {=IFERROR(INDEX('REF1'!B:K,SMALL('REF1'!K:K,ROW()-11),8),"")} | I43: =IFERROR(_xlfn.XLOOKUP(A43,'LISTADO GENERAL '!B45:B2208,'LISTADO GENERAL '!A45:A2208),"")
A44: {=IFERROR(INDEX('REF1'!B:K,SMALL('REF1'!K:K,ROW()-11),1),"")} | B44: {=IFERROR(INDEX('REF1'!B:K,SMALL('REF1'!K:K,ROW()-11),3),"")} | C44: {=IFERROR(INDEX('REF1'!B:K,SMALL('REF1'!K:K,ROW()-11),2),"")} | D44: {=IFERROR(INDEX('REF1'!B:K,SMALL('REF1'!K:K,ROW()-11),5),"")} | E44: {=IFERROR(INDEX('REF1'!B:K,SMALL('REF1'!K:K,ROW()-11),4),"")} | F44: {=IFERROR(INDEX('REF1'!B:K,SMALL('REF1'!K:K,ROW()-11),6),"")} | G44: {=IFERROR(INDEX('REF1'!B:K,SMALL('REF1'!K:K,ROW()-11),7),"")} | H44: {=IFERROR(INDEX('REF1'!B:K,SMALL('REF1'!K:K,ROW()-11),8),"")} | I44: =IFERROR(_xlfn.XLOOKUP(A44,'LISTADO GENERAL '!B46:B2208,'LISTADO GENERAL '!A46:A2208),"")
A45: {=IFERROR(INDEX('REF1'!B:K,SMALL('REF1'!K:K,ROW()-11),1),"")} | B45: {=IFERROR(INDEX('REF1'!B:K,SMALL('REF1'!K:K,ROW()-11),3),"")} | C45: {=IFERROR(INDEX('REF1'!B:K,SMALL('REF1'!K:K,ROW()-11),2),"")} | D45: {=IFERROR(INDEX('REF1'!B:K,SMALL('REF1'!K:K,ROW()-11),5),"")} | E45: {=IFERROR(INDEX('REF1'!B:K,SMALL('REF1'!K:K,ROW()-11),4),"")} | F45: {=IFERROR(INDEX('REF1'!B:K,SMALL('REF1'!K:K,ROW()-11),6),"")} | G45: {=IFERROR(INDEX('REF1'!B:K,SMALL('REF1'!K:K,ROW()-11),7),"")} | H45: {=IFERROR(INDEX('REF1'!B:K,SMALL('REF1'!K:K,ROW()-11),8),"")} | I45: =IFERROR(_xlfn.XLOOKUP(A45,'LISTADO GENERAL '!B47:B2208,'LISTADO GENERAL '!A47:A2208),"")
...

Sheet LISTADO GENERAL 
V11: TASA
V12: 66.55
A13: FILTRO | B13: CODIGO INTERNO | C13: EAN 13 | D13: CATEGORIA | E13: PRODUCTO | F13: ALMAC | G13: STK | H13: COMPONENTE ACTIVO | I13: LAB | J13: UNIDAD MANEJO | K13: IVA / EXENTO | L13: ACCION TERAPEUTICA | M13: $ PRECIO ANTES | N13: % DTO | O13: $ PRECIO NETO | P13: PRECIO REF Bs | Q13: $ PRECIO CON IVA | R13: LAB ORIGEN | S13: VENCE | T13: PEDIDO (UNIDS) | U13: TOTAL ($) | V13: 45733
A14: PRODUCTOS TOP | B14: 040230007 | C14: 742033994719 | D14: MATERIAL MEDICO DESCARTABLE | E14: APOSITOS KIDS BRIUTCARE (KIDS CURITAS) X 20 UND | G14: 107 | H14: N/A | I14: BRIUTCARE | J14: UNIDAD | K14: 0.16 | L14: N/A | M14: 1.5103545 | N14: 0 | O14: 1.5103545 | P14: =O14*$V$12 -> 100.51409 | Q14: 1.7520112 | R14: CHINA | S14: 47119 | U14: =+T14*Q14 -> 0
B15: 000939 | C15: 7894164005802 | D15: IMPORTADOS | E15: SULFATO FERROSO 125 MG/ML X 30 ML GOTAS | G15: 100 | H15: SULFATO FERROSO | I15: RJR | J15: UNIDAD | K15: EXENTO | L15: SANGRE, LÍQUIDOS Y ELECTRÓLITOS - ANTIANÉMICOS | M15: 1.5324675 | N15: 0 | O15: 1.5324675 | P15: =O15*$V$12 -> 101.98571 | Q15: 1.5324675 | R15: BRASIL | S15: 46174 | U15: =+T15*Q15 -> 0
A16: MORADO DE BIENESTAR | B16: 033730000 | C16: 7598055000418 | D16: IMPORTADOS | E16: ABECAB 5/20 MG ( AMLODIPINO - OLMESARTAN) X 30 TAB | G16: 116 | H16: ANTIESTATICO Y ANTIEMPAÑANTES | I16: CAPSUVEN | J16: UNIDAD | K16: EXENTO | L16: N/A | M16: 4.4261905 | N16: 0.2 | O16: 2.2130952 | P16: =O16*$V$12 -> 147.28149 | Q16: 2.2130952 | R16: BANGLADESH | S16: 46508 | U16: =+T16*Q16 -> 0
A17: MORADO DE BIENESTAR | B17: 0337300023 | C17: 7598055000425 | D17: IMPORTADOS | E17: ABECAB 5-40 mg X 30 TAB | G17: 60 | H17: ANTIESTATICO Y ANTIEMPAÑANTES | I17: CAPSUVEN | J17: UNIDAD | K17: EXENTO | L17: N/A | M17: 9.3376623 | N17: 0.1 | O17: 5.6025974 | P17: =O17*$V$12 -> 372.85286 | Q17: 5.6025974 | R17: BANGLADESH | S17: 45870 | U17: =+T17*Q17 -> 0
B18: 000930 | C18: 7894164008735 | D18: IMPORTADOS | E18: ABIDOR GOTAS 200 MG 2 ML-15 ML TUTTI FRUTTI | G18: 100 | H18: PARACETAMOL | I18: RJR | J18: UNIDAD | K18: EXENTO | L18: SISTEMA NERVIOSO - ANALGÉSICOS, SISTEMA NERVIOSO - ANTIPIRÉTICOS | M18: 0.81818182 | N18: 0 | O18: 0.81818182 | P18: =O18*$V$12 -> 54.45 | Q18: 0.81818182 | R18: BRASIL | S18: 46113 | U18: =+T18*Q18 -> 0
A19: PRODUCTOS TOP | B19: 023690016 | C19: 7730969307683 | D19: NACIONALES | E19: ABINTRA SABOR NARANJA X 27 g POLVO | G19: 18 | H19: ARGININA - GLUTAMINA - PROTEINA - VITAMINAS | I19: MEGALABS | J19: UNIDAD | K19: EXENTO | L19: LECHES, VITAMINAS Y NUTRIENTES - VITAMINAS, MINERALES, OLIGOELEMENTOS | M19: 7.1392405 | N19: 0.15 | O19: 6.0683544 | P19: =O19*$V$12 -> 403.84899 | Q19: 6.0683544 | R19: VENEZUELA | S19: 46174 | U19: =+T19*Q19 -> 0
A20: PRODUCTOS TOP | B20: 021430797 | C20: 7591619520896 | D20: NACIONALES | E20: ABRETIA 18MG X 10 CAP | G20: 21 | H20: ATOMOXETINA | I20: MEGALABS | J20: UNIDAD | K20: EXENTO | L20: ANTIINFECCIOSOS SISTÉMICOS - ANTIBIÓTICOS | M20: 24.810127 | N20: 0.08 | O20: 22.825316 | P20: =O20*$V$12 -> 1519.0248 | Q20: 22.825316 | R20: VENEZUELA | S20: 46539 | U20: =+T20*Q20 -> 0
A21: PRODUCTOS TOP | B21: 023630001 | C21: 7803510003669 | D21: NACIONALES | E21: ACCUALAXAN POLVO PARA SOL.MACROGOL 3350 SOBRE X 17grs | G21: 60 | H21: MACROGOL 3350 | I21: GARDEN HOUSE | J21: UNIDAD | K21: EXENTO | L21: APARATO DIGESTIVO - LAXANTES - CATÁRTICOS - ENEMAS | M21: 1.4922619 | N21: 0.6 | O21: 0.59690476 | P21: =O21*$V$12 -> 39.724012 | Q21: 0.59690476 | R21: VENEZUELA | S21: 46054 | U21: =+T21*Q21 -> 0
A22: PRODUCTOS TOP | B22: 023630000 | C22: 7803510003638 | D22: NACIONALES | E22: ACCUALAXAN POLVO PARA SOL.MACROGOL 3350 X 255g PARA 15 DOSIS | G22: 10 | H22: MACROGOL 3350 | I22: GARDEN HOUSE | J22: UNIDAD | K22: EXENTO | L22: APARATO DIGESTIVO - LAXANTES - CATÁRTICOS - ENEMAS | M22: 9.6333333 | N22: 0.6 | O22: 3.8533333 | P22: =O22*$V$12 -> 256.43933 | Q22: 3.8533333 | R22: CHILE | S22: 46054 | U22: =+T22*Q22 -> 0
A23: BROCHE DE ORO | B23: 021091126 | C23: 7795380002333 | D23: NACIONALES | E23: ACEMUK (ACETILCISTEINA ) 200 MG X 10 TAB | G23: 46 | H23: ACETILCISTEINA | I23: MEYER | J23: UNIDAD | K23: EXENTO | L23: APARATO RESPIRATORIO - ANTITUSIVOS, EXPECTORANTES, MUCOLÍTICOS | M23: 14.809524 | N23: 0.05 | O23: 12.691 | P23: =O23*$V$12 -> 844.58605 | Q23: 14.069048 | R23: ARGENTINA | S23: 45809 | U23: =+T23*Q23 -> 0
A24: BROCHE DE ORO | B24: 021181061 | C24: 7591196004802 | D24: NACIONALES | E24: ACETAB 250MG X 20 TAB | G24: 80 | H24: ACETAZOLAMIDA | I24: OFTALMI | J24: UNIDAD | K24: EXENTO | L24: SISTEMA NERVIOSO - ANTICONVULSIVOS - ANTIEPILÉPTICOS | M24: 14.487519 | N24: 0 | O24: 12.4852 | P24: =O24*$V$12 -> 830.89006 | Q24: 14.487519 | R24: VENEZUELA | S24: 46174 | U24: =+T24*Q24 -> 0
B25: 7591616002142 | C25: 7591616002142 | D25: NACIONALES | E25: ACETAFEN FORTE 180 MG / 5 ML X 120 ML JBE | G25: 24 | H25: ACETAMINOFEN | I25: BIOFARCO | J25: UNIDAD | K25: EXENTO | L25: ANTIPIRETICO | M25: 3.0467532 | N25: 0 | O25: 3.0467532 | P25: =O25*$V$12 -> 202.76143 | Q25: 3.0467532 | R25: VENEZUELA | S25: 46235 | U25: =+T25*Q25 -> 0
A26: PRODUCTOS TOP | B26: 030960804 | C26: 7703038065630 | D26: IMPORTADOS | E26: ACETAMINOFEN JARABE 150MG/5ML FRASCO X 90ML | G26: 132 | H26: ACETAMINOFEN | I26: LAPROFF | J26: UNIDAD | K26: EXENTO | L26: SISTEMA NERVIOSO - ANTIPIRÉTICOS | M26: 1.7777381 | N26: 0 | O26: 1.7777381 | P26: =O26*$V$12 -> 118.30847 | Q26: 1.7777381 | R26: COLOMBIA | S26: 46600 | U26: =+T26*Q26 -> 0
A27: PRODUCTOS TOP | B27: 030960793 | C27: 7703038067269 | D27: IMPORTADOS | E27: ACETAMINOFEN JARABE PEDIATRICO X 120ML | G27: 382 | H27: ACETAMINOFEN | I27: LAPROFF | J27: UNIDAD | K27: EXENTO | L27: SISTEMA NERVIOSO - ANTIPIRÉTICOS | M27: 2.0761905 | N27: 0 | O27: 2.0761905 | P27: =O27*$V$12 -> 138.17048 | Q27: 2.0761905 | R27: COLOMBIA | S27: 46600 | U27: =+T27*Q27 -> 0
A28: PRODUCTOS TOP | B28: 020350848 | C28: 7591818132074 | D28: NACIONALES | E28: ACETAMINOFEN 120MG/5ML X 120ML JARABE | G28: 1341 | H28: ACETAMINOFEN | I28: COFASA | J28: UNIDAD | K28: EXENTO | L28: SISTEMA NERVIOSO - ANTIPIRÉTICOS | M28: 2.6048816 | N28: 0.15 | O28: 2.2141493 | P28: =O28*$V$12 -> 147.35164 | Q28: 2.2141493 | R28: VENEZUELA | S28: 46631 | U28: =+T28*Q28 -> 0
A29: BROCHE DE ORO | B29: 020930005 | C29: 7592454003100 | D29: NACIONALES | E29: ACETAMINOFEN 150mg X 120ml JARABE | G29: 402 | H29: ACETAMINOFEN | I29: LA SANTE | J29: UNIDAD | K29: EXENTO | L29: SISTEMA NERVIOSO - ANTIPIRÉTICOS | M29: 2.8181818 | N29: 0 | O29: 1.9012 | P29: =O29*$V$12 -> 126.52486 | Q29: 2.8181818 | R29: VENEZUELA | S29: 46478 | U29: =+T29*Q29 -> 0
A30: BROCHE DE ORO | B30: 020981161 | C30: 7591585177780 | D30: NACIONALES | E30: ACETAMINOFEN 180mg/5mL PEDIATRICO X 90 mL | G30: 216 | H30: ACETAMINOFEN | I30: LETI-GENVEN | J30: UNIDAD | K30: EXENTO | L30: SISTEMA NERVIOSO - ANTIPIRÉTICOS | M30: 2.4050633 | N30: 0 | O30: 2.2848101 | P30: =O30*$V$12 -> 152.05411 | Q30: 2.2848101 | R30: VENEZUELA | S30: 46296 | U30: =+T30*Q30 -> 0
A31: BROCHE DE ORO | B31: 023760019 | C31: 7598455000537 | D31: IMPORTADOS | E31: ACETAMINOFEN 180MG/5ML X 120 ML SOL ORAL | G31: 78 | H31: ACETAMINOFEN | I31: BIOGLASS | J31: UNIDAD | K31: EXENTO | M31: 1.9350649 | N31: 0 | O31: 1.8383117 | P31: =O31*$V$12 -> 122.33964 | Q31: 1.8383117 | R31: INDIA | S31: 46327 | U31: =+T31*Q31 -> 0
B32: 020261126 | C32: 7591519004144 | D32: NACIONALES | E32: ACETAMINOFEN 500 X 10 TAB | G32: 500 | H32: ACETAMINOFEN | I32: CALOX | J32: UNIDAD | K32: EXENTO | L32: SISTEMA NERVIOSO - ANTIPIRETICOS | M32: 0.79090909 | N32: 0.02 | O32: 0.77509091 | P32: =O32*$V$12 -> 51.5823 | Q32: 0.77509091 | R32: VENEZUELA | S32: 46692 | U32: =+T32*Q32 -> 0
A33: BROCHE DE ORO | B33: 020981087 | C33: 7591585376657 | D33: NACIONALES | E33: ACETAMINOFEN 500mg X 10 COMPR | G33: 2455 | H33: ACETAMINOFEN | I33: LETI-GENVEN | J33: UNIDAD | K33: EXENTO | L33: SISTEMA NERVIOSO - ANTIPIRÉTICOS | M33: 0.72727273 | N33: 0 | O33: 0.69090909 | P33: =O33*$V$12 -> 45.98 | Q33: 0.69090909 | R33: VENEZUELA | S33: 46054 | U33: =+T33*Q33 -> 0
A34: BROCHE DE ORO | B34: 021181140 | C34: 7591196006516 | D34: NACIONALES | E34: ACETAMINOFEN 500MG X 10 TAB | G34: 1140 | H34: ACETAMINOFEN | I34: OFTALMI | J34: UNIDAD | K34: EXENTO | L34: ANALGESICO-ANTIFLAMATORIO | M34: 0.78155844 | N34: 0.15 | O34: 0.6174 | P34: =O34*$V$12 -> 41.08797 | Q34: 0.66432468 | R34: VENEZUELA | S34: 46631 | U34: =+T34*Q34 -> 0
A35: BROCHE DE ORO | B35: 020930560 | C35: 7592454000031 | D35: NACIONALES | E35: ACETAMINOFEN 500MG X 20 TAB | G35: 74 | H35: ACETAMINOFEN | I35: LA SANTE | J35: UNIDAD | K35: EXENTO | L35: SISTEMA NERVIOSO - ANTIPIRÉTICOS | M35: 1.5696203 | N35: 0 | O35: 1.2838 | P35: =O35*$V$12 -> 85.43689 | Q35: 1.5696203 | R35: VENEZUELA | S35: 46266 | U35: =+T35*Q35 -> 0
A36: BROCHE DE ORO | B36: 021181141 | C36: 7591196006523 | D36: NACIONALES | E36: ACETAMINOFEN 500MG X 30 TAB | G36: 267 | H36: ACETAMINOFEN | I36: OFTALMI | J36: UNIDAD | K36: EXENTO | L36: ANALGESICO-ANTIFLAMATORIO | M36: 2.038961 | N36: 0 | O36: 1.8228 | P36: =O36*$V$12 -> 121.30734 | Q36: 2.038961 | R36: VENEZUELA | S36: 46478 | U36: =+T36*Q36 -> 0
B37: 020261139 | C37: 7591519005264 | D37: NACIONALES | E37: ACETAMINOFEN 650 mg X 10 TAB | G37: 108 | H37: ACETAMINOFEN | I37: CALOX | J37: UNIDAD | K37: EXENTO | L37: SISTEMA NERVIOSO - ANTIPIRETICOS | M37: 0.85714286 | N37: 0 | O37: 0.85714286 | P37: =O37*$V$12 -> 57.042857 | Q37: 0.85714286 | R37: VENEZUELA | S37: 46661 | U37: =+T37*Q37 -> 0
A38: BROCHE DE ORO | B38: 020980978 | C38: 7591585279057 | D38: NACIONALES | E38: ACETAMINOFEN 650mg X 10 COMPR | G38: 3179 | H38: ACETAMINOFEN | I38: LETI-GENVEN | J38: UNIDAD | K38: EXENTO | L38: SISTEMA NERVIOSO - ANTIPIRÉTICOS | M38: 0.66233766 | N38: 0 | O38: 0.62922078 | P38: =O38*$V$12 -> 41.874643 | Q38: 0.62922078 | R38: VENEZUELA | S38: 46054 | U38: =+T38*Q38 -> 0
A39: BROCHE DE ORO | B39: 020930002 | C39: 7592454001243 | D39: NACIONALES | E39: ACETAMINOFEN 650MG X 10 TAB | G39: 2245 | H39: ACETAMINOFEN | I39: LA SANTE | J39: UNIDAD | K39: EXENTO | L39: SISTEMA NERVIOSO - ANTIPIRÉTICOS | M39: 0.90909091 | N39: 0.47 | O39: 0.343 | P39: =O39*$V$12 -> 22.82665 | Q39: 0.48181818 | R39: VENEZUELA | S39: 46174 | U39: =+T39*Q39 -> 0
B40: 021260999 | C40: 7594001101604 | D40: NACIONALES | E40: ACETAMINOFEN 650MG x 10 TABL | G40: 7 | H40: ACETAMINOFEN | I40: PLUS ANDES | J40: UNIDAD | K40: EXENTO | L40: SISTEMA NERVIOSO - ANTIPIRÉTICOS | M40: 0.7357209 | N40: 0.05 | O40: 0.69893485 | P40: =O40*$V$12 -> 46.514114 | Q40: 0.69893485 | R40: VENEZUELA | S40: 46204 | U40: =+T40*Q40 -> 0
A41: BROCHE DE ORO | B41: 020980003 | C41: 7591585179050 | D41: NACIONALES | E41: ACETAMINOFEN 650mg X 30 COMPR | G41: 352 | H41: ACETAMINOFEN | I41: LETI-GENVEN | J41: UNIDAD | K41: EXENTO | L41: SISTEMA NERVIOSO - ANTIPIRÉTICOS | M41: 1.7662338 | N41: 0 | O41: 1.6779221 | P41: =O41*$V$12 -> 111.66571 | Q41: 1.6779221 | R41: VENEZUELA | S41: 46235 | U41: =+T41*Q41 -> 0
A42: BROCHE DE ORO | B42: 020981135 | C42: - | D42: NACIONALES | E42: ACETAMINOFEN 650mg X 8 BLIST X 10COMP | G42: 15 | H42: ACETAMINOFEN | I42: LETI-GENVEN | J42: UNIDAD | K42: EXENTO | L42: SISTEMA NERVIOSO - ANTIPIRÉTICOS | M42: 8.0711905 | N42: 0 | O42: 7.667631 | P42: =O42*$V$12 -> 510.28084 | Q42: 7.667631 | R42: VENEZUELA | S42: 46113 | U42: =+T42*Q42 -> 0
B43: 0217208283 | C43: 8904187887855 | D43: NACIONALES | E43: ACETAMINOFEN 650mg-CAFEINA 65mg X 10 TAB | G43: 56 | H43: ACETAMINOFEN - CAFEINA | I43: VINCENTI | J43: UNIDAD | K43: EXENTO | L43: SISTEMA NERVIOSO - ANALGÉSICOS | M43: 2.0476028 | N43: 0 | O43: 2.0476028 | P43: =O43*$V$12 -> 136.26797 | Q43: 2.0476028 | R43: VENEZUELA | S43: 45931 | U43: =+T43*Q43 -> 0
B44: 023800000 | C44: 7594000851289 | D44: NACIONALES | E44: ACETAMINOFEN 750 MG X 10 COMP | G44: 174 | H44: ACETAMINOFEN | I44: BIOQUIMICA | J44: UNIDAD | K44: EXENTO | L44: SISTEMA NERVIOSO - ANTIPIRÉTICOS | M44: 2.4155844 | N44: 0.05 | O44: 2.2948052 | P44: =O44*$V$12 -> 152.71929 | Q44: 2.2948052 | R44: VENEZUELA | S44: 46023 | U44: =+T44*Q44 -> 0
A45: PRODUCTOS TOP | B45: 0339000000 | C45: 6942189530302 | D45: IMPORTADOS | E45: ACETAMINOFEN PEDIATRICO 120 mg / 5 mL X 100 mL JBE | G45: 2 | H45: ACETAMINOFEN | I45: KMPLUS | J45: UNIDAD | K45: EXENTO | L45: SISTEMA NERVIOSO - ANTIPIRÉTICOS | M45: 1.3896104 | N45: 0.1 | O45: 1.2506494 | P45: =O45*$V$12 -> 83.230714 | Q45: 1.2506494 | R45: CHIINA | S45: 46266 | U45: =+T45*Q45 -> 0
A46: PRODUCTOS TOP | B46: 0339000019 | C46: 6942189530296 | D46: IMPORTADOS | E46: ACETAMINOFEN PEDIATRICO 120 mg / 5 mL X 60 mL JBE | G46: 40 | H46: ACETAMINOFEN | I46: KMPLUS | J46: UNIDAD | K46: EXENTO | L46: SISTEMA NERVIOSO - ANTIPIRÉTICOS | M46: 1.3246753 | N46: 0.1 | O46: 1.1922078 | P46: =O46*$V$12 -> 79.341429 | Q46: 1.1922078 | R46: CHIINA | S46: 46266 | U46: =+T46*Q46 -> 0
A47: BROCHE DE ORO | B47: 021181133 | C47: 7591196006387 | D47: NACIONALES | E47: ACETAMINOFEN SOL PED 120mg/5mL X 120mL | G47: 57 | H47: ACETAMINOFEN | I47: OFTALMI | J47: UNIDAD | K47: EXENTO | L47: ANALGESICO-ANTIFLAMATORIO | M47: 3.0649351 | N47: 0 | O47: 2.107 | P47: =O47*$V$12 -> 140.22085 | Q47: 3.0649351 | R47: VENEZUELA | S47: 46419 | U47: =+T47*Q47 -> 0
A48: BROCHE DE ORO | B48: 021181119 | C48: 7591196006486 | D48: NACIONALES | E48: ACETAMINOFEN SOL PED 120mg/5mL X 60mL | G48: 709 | H48: ACETAMINOFEN | I48: OFTALMI | J48: UNIDAD | K48: EXENTO | L48: ANALGESICO-ANTIFLAMATORIO | M48: 1.6455696 | N48: 0 | O48: 1.1956 | P48: =O48*$V$12 -> 79.56718 | Q48: 1.6455696 | R48: VENEZUELA | S48: 46296 | U48: =+T48*Q48 -> 0
B49: 030060000 | C49: 8904307705625 | D49: IMPORTADOS | E49: ACETATO DE DEXAMETASONA+ CLOTRIMAZOL X 20 CREMA | G49: 100 | H49: DEXAMETASONA CLOTRIMAZOL | I49: ALFA FARMACEUTICAL | J49: UNIDAD | K49: EXENTO | L49: ANTIINFECCIOSOS SISTÉMICOS - ANTIMICÓTICOS, APARATO LOCOMOTOR - ANTIINFLAMATORIOS NO ESTEROIDES (AINE) | M49: 1.9168831 | N49: 0.5 | O49: 0.95844156 | P49: =O49*$V$12 -> 63.784286 | Q49: 0.95844156 | R49: INDIA | S49: 45992 | U49: =+T49*Q49 -> 0
B50: 021460796 | C50: 7592806121018 | D50: NACIONALES | E50: ACETOBEN NF X 120ML | G50: 2 | H50: GUAIFENESINA | I50: RONAVA | J50: UNIDAD | K50: EXENTO | L50: APARATO RESPIRATORIO - ANTITUSIVOS, EXPECTORANTES, MUCOLÍTICOS | M50: 5.3840506 | N50: 0.1 | O50: 4.8456456 | P50: =O50*$V$12 -> 322.47771 | Q50: 4.8456456 | R50: VENEZUELA | S50: 46478 | U50: =+T50*Q50 -> 0
...

Sheet MISCELANEOS
V11: TASA
V12: =+'LISTADO GENERAL '!V12 -> 66.55
A13: FILTRO | B13: CODIGO INTERNO | C13: EAN 13 | D13: CATEGORIA | E13: PRODUCTO | F13: 001 | G13: STK | H13: COMPONENTE ACTIVO | I13: LAB | J13: UNIDAD MANEJO | K13: IVA / EXENTO | L13: ACCION TERAPEUTICA | M13: $ PRECIO ANTES | N13: % DTO | O13: $ PRECIO NETO | P13: PRECIO REF Bs | Q13: $ PRECIO CON IVA | R13: LAB ORIGEN | S13: VENCE | T13: PEDIDO (UNIDS) | U13: TOTAL ($) | V13: =+'LISTADO GENERAL '!V13 -> 45733
A14: PRODUCTOS TOP | B14: 7591616000032 | C14: 7591616000032 | D14: MISCELANEOS | E14: ACEITE DE ALMENDRAS DULCES X 30 ML SOL | F14: 001 | G14: 19 | H14: N/A | I14: BIOFARCO | J14: UNIDAD | K14: EXENTO | L14: N/A | M14: 2.1118182 | N14: 0 | O14: 2.1118182 | P14: =O14*$V$12 -> 140.5415 | Q14: 2.1118182 | R14: VENEZUELA | S14: 46539 | U14: =+T14*Q14 -> 0
B15: 7591616000056 | C15: 7591616000056 | D15: MISCELANEOS | E15: ACEITE DE COCO X 30 ML SOL | F15: 001 | G15: 16 | H15: N/A | I15: BIOFARCO | J15: UNIDAD | K15: EXENTO | L15: N/A | M15: 2.987013 | N15: 0 | O15: 2.987013 | P15: =O15*$V$12 -> 198.78571 | Q15: 2.987013 | R15: VENEZUELA | S15: 46661 | U15: =+T15*Q15 -> 0
A16: PRODUCTOS TOP | B16: 7591616000131 | C16: 7591616000131 | D16: MISCELANEOS | E16: ACEITE DE RICINO X 30 ML SOL | F16: 001 | G16: 6 | H16: N/A | I16: BIOFARCO | J16: UNIDAD | K16: EXENTO | L16: N/A | M16: 2.8701299 | N16: 0 | O16: 2.8701299 | P16: =O16*$V$12 -> 191.00714 | Q16: 2.8701299 | R16: VENEZUELA | S16: 46631 | U16: =+T16*Q16 -> 0
B17: 052670024 | C17: 7591012030008 | D17: MISCELANEOS | E17: ACEITE MINERAL 30 ML | F17: 001 | G17: 15 | H17: ACEITE MINERAL GRADO USP | I17: LYA | J17: UNIDAD | K17: EXENTO | L17: PIEL Y MUCOSAS - DERMATOCOSMÉTICOS | M17: 2.5222222 | N17: 0 | O17: 2.5222222 | P17: =O17*$V$12 -> 167.85389 | Q17: 2.5222222 | R17: VENEZUELA | S17: 45931 | U17: =+T17*Q17 -> 0
B18: 7591616000162 | C18: 7591616000162 | D18: MISCELANEOS | E18: ACEITE MINIRAL X 30 ML SOL | F18: 001 | G18: 24 | H18: N/A | I18: BIOFARCO | J18: UNIDAD | K18: EXENTO | L18: N/A | M18: 2.012987 | N18: 0 | O18: 2.012987 | P18: =O18*$V$12 -> 133.96429 | Q18: 2.012987 | R18: VENEZUELA | S18: 46661 | U18: =+T18*Q18 -> 0
A19: PRODUCTOS TOP | B19: 7591616001466 | C19: 7591616001466 | D19: MISCELANEOS | E19: ACIDO BORICO X 20 GR POLVO SOBRE | F19: 001 | G19: 24 | H19: ACETAMINOFEN | I19: BIOFARCO | J19: UNIDAD | K19: EXENTO | L19: ANTIPIRETICO | M19: 1.3766234 | N19: 0 | O19: 1.3766234 | P19: =O19*$V$12 -> 91.614286 | Q19: 1.3766234 | R19: VENEZUELA | S19: 46661 | U19: =+T19*Q19 -> 0
B20: 050280004 | C20: 190679004772 | D20: MISCELANEOS | E20: ACONDICIONADOR HERBAL ESSENCES HELLO HYDRATION 346ML | F20: 001 | G20: 2 | H20: ACONDICIONADOR | I20: P&G | J20: UNIDAD | K20: 0.16 | L20: N/A | M20: 5.2555556 | N20: 0 | O20: 5.2555556 | P20: =O20*$V$12 -> 349.75722 | Q20: 6.0964444 | R20: ESTADOS UNIDOS | S20: 46174 | U20: =+T20*Q20 -> 0
A21: PRODUCTOS TOP | B21: 052280225 | C21: 7591309003692 | D21: MISCELANEOS | E21: ADEL UNGÜENTO X 50GR | F21: 001 | G21: 70 | H21: LANOLINA | I21: PONCE & BENZO | J21: UNIDAD | K21: 0.16 | L21: PIEL Y MUCOSAS - ANTIPRURIGINOSOS TÓPICOS | M21: 4.0253165 | N21: 0 | O21: 4.0253165 | P21: =O21*$V$12 -> 267.88481 | Q21: 4.6693671 | R21: VENEZUELA | S21: 46569 | U21: =+T21*Q21 -> 0
B22: 050210003 | C22: 7702018001071 | D22: MISCELANEOS | E22: AFEITADORA MACH3 BASE RAZOR | F22: 001 | G22: 22 | H22: N/A | I22: P&G | J22: UNIDAD | K22: 0.16 | L22: N/A | M22: 7.9444444 | N22: 0 | O22: 7.9444444 | P22: =O22*$V$12 -> 528.70278 | Q22: 9.2155556 | R22: MEXICO | S22: 0 | U22: =+T22*Q22 -> 0
B23: 050210006 | C23: 047400025073 | D23: MISCELANEOS | E23: AFEITADORA DESECHABLE GILLETTE DAISY CLASSIC X 2 UNIDADES | F23: 001 | G23: 30 | H23: N/A | I23: P&G | J23: UNIDAD | K23: 0.16 | L23: N/A | M23: 3.6111111 | N23: 0 | O23: 3.6111111 | P23: =O23*$V$12 -> 240.31944 | Q23: 4.1888889 | R23: MEXICO | S23: 0 | U23: =+T23*Q23 -> 0
B24: 050210005 | C24: 047400313910 | D24: MISCELANEOS | E24: AFEITADORA DESECHABLE VENUS GILLETTE DISP 3 UNI TROPICAL | F24: 001 | G24: 8 | H24: N/A | I24: P&G | J24: UNIDAD | K24: 0.16 | L24: N/A | M24: 14.022222 | N24: 0 | O24: 14.022222 | P24: =O24*$V$12 -> 933.17889 | Q24: 16.265778 | R24: CANADA | S24: 0 | U24: =+T24*Q24 -> 0
B25: 050210004 | C25: 7702018037803 | D25: MISCELANEOS | E25: AFEITADORA MACH3 SENSITIVE -BASE RAZOR | F25: 001 | G25: 3 | H25: N/A | I25: P&G | J25: UNIDAD | K25: 0.16 | L25: N/A | M25: 9.7380952 | N25: 0 | O25: 9.7380952 | P25: =O25*$V$12 -> 648.07024 | Q25: 11.29619 | R25: MEXICO | S25: 0 | U25: =+T25*Q25 -> 0
B26: 059990220 | C26: 7501014590448 | D26: MISCELANEOS | E26: AFEITADORA SHAVER SENB BIC RISTRA X 12 | F26: 001 | G26: 44 | H26: N/A | I26: SANOZ | J26: UNIDAD | K26: 0.16 | L26: N/A | M26: 5.1444444 | N26: 0 | O26: 5.1444444 | P26: =O26*$V$12 -> 342.36278 | Q26: 5.9675556 | R26: FRANCIA | S26: 45778 | U26: =+T26*Q26 -> 0
B27: 050210007 | C27: 7506309841762 | D27: MISCELANEOS | E27: AFEITADORA VENUS GILLETTE RAZOR 1 UP | F27: 001 | G27: 4 | H27: MAQUINA PARA AFEITAR RECARGABLE | I27: P&G | J27: UNIDAD | K27: 0.16 | L27: N/A | M27: 7.7738095 | N27: 0 | O27: 7.7738095 | P27: =O27*$V$12 -> 517.34702 | Q27: 9.017619 | R27: MEXICO | S27: 0 | U27: =+T27*Q27 -> 0
B28: 051440007 | C28: 7592871004865 | D28: MISCELANEOS | E28: AGUA OXIGENADA VOL 30 X 500CC | F28: 001 | G28: 156 | H28: PEROXIDO DE HIDROGENO | I28: ROLDA | J28: UNIDAD | K28: 0.16 | L28: N/A | M28: 2.9111111 | N28: 0 | O28: 2.9111111 | P28: =O28*$V$12 -> 193.73444 | Q28: 3.3768889 | R28: VENEZUELA | S28: 45962 | U28: =+T28*Q28 -> 0
A29: PRODUCTOS TOP | B29: 7591616001480 | C29: 7591616001480 | D29: MISCELANEOS | E29: ALUMBRE X 20 GR POLVO SOBRE | F29: 001 | G29: 24 | H29: N/A | I29: BIOFARCO | J29: UNIDAD | K29: EXENTO | L29: N/A | M29: 1.2077922 | N29: 0 | O29: 1.2077922 | P29: =O29*$V$12 -> 80.378571 | Q29: 1.2077922 | R29: VENEZUELA | S29: 46661 | U29: =+T29*Q29 -> 0
A30: PRODUCTOS TOP | B30: 020640938 | C30: 7592349911244 | D30: MISCELANEOS | E30: ANDANTOL JALEA X 20 G N.F. | F30: 001 | G30: 21 | H30: Aceite de Mentol-Aceite esencial de Alcanfor-Esencia de Arnica | I30: VARGAS | J30: UNIDAD | K30: EXENTO | L30: PIEL Y MUCOSAS - ANTISÉPTICOS, DESINFECTANTES Y CICATRIZANTES | M30: 4.443038 | N30: 0 | O30: 4.443038 | P30: =O30*$V$12 -> 295.68418 | Q30: 4.443038 | R30: VENEZUELA | S30: 45870 | U30: =+T30*Q30 -> 0
B31: 7591616001510 | C31: 7591616001510 | D31: MISCELANEOS | E31: AZUFRE X 20 GR POLVO SOBRE | F31: 001 | G31: 24 | H31: N/A | I31: BIOFARCO | J31: UNIDAD | K31: EXENTO | L31: N/A | M31: 1.1863636 | N31: 0 | O31: 1.1863636 | P31: =O31*$V$12 -> 78.9525 | Q31: 1.1863636 | R31: VENEZUELA | S31: 46631 | U31: =+T31*Q31 -> 0
B32: 053810004 | C32: 7598084000991 | D32: MISCELANEOS | E32: BRONCEADOR EN CREMA 160G | F32: 001 | G32: 22 | H32: N/A | I32: DERNIER | J32: UNIDAD | K32: 0.16 | L32: N/A | M32: 4.3896104 | N32: 0 | O32: 4.3896104 | P32: =O32*$V$12 -> 292.12857 | Q32: 5.0919481 | R32: VENEZUELA | S32: 46054 | U32: =+T32*Q32 -> 0
B33: 022260863 | C33: 7592090000334 | D33: MISCELANEOS | E33: BRUCEN ADULTCARE BODY LOTION X 250ML | F33: 001 | G33: 60 | H33: PRO VITAMINA B5+E D-PANTHENOL | I33: BRUPHARM | J33: UNIDAD | K33: 0.16 | L33: N/A | M33: 9.1135443 | N33: 0 | O33: 9.1135443 | P33: =O33*$V$12 -> 606.50637 | Q33: 10.571711 | R33: VENEZUELA | S33: 46631 | U33: =+T33*Q33 -> 0
A34: PRODUCTOS TOP | B34: 022260862 | C34: 7592090000167 | D34: MISCELANEOS | E34: BRUCEN ADULTCARE BODY LOTION X 400ML | F34: 001 | G34: 9 | H34: PRO VITAMINA B5+E D-PANTHENOL | I34: BRUPHARM | J34: UNIDAD | K34: 0.16 | L34: N/A | M34: 11.737975 | N34: 0 | O34: 11.737975 | P34: =O34*$V$12 -> 781.16222 | Q34: 13.616051 | R34: VENEZUELA | S34: 46082 | U34: =+T34*Q34 -> 0
B35: 022260912 | C35: 7592090000020 | D35: MISCELANEOS | E35: BRUCEN ADULTCARE CREMA DERMOPROTECTORA PARA ADULTOS X 100GR | F35: 001 | G35: 24 | H35: N/A | I35: BRUPHARM | J35: UNIDAD | K35: 0.16 | L35: N/A | M35: 7.0330952 | N35: 0 | O35: 7.0330952 | P35: =O35*$V$12 -> 468.05249 | Q35: 8.1583905 | R35: VENEZUELA | S35: 46692 | U35: =+T35*Q35 -> 0
B36: 022260911 | C36: 7592090000075 | D36: MISCELANEOS | E36: BRUCEN ADULTCARE CREMA DERMORESTAURADORA CENTELLA ASIATICA X 30GR | F36: 001 | G36: 24 | H36: CENTELLA ASIATICA | I36: BRUPHARM | J36: UNIDAD | K36: 0.16 | L36: PIEL Y MUCOSAS - ANTISÉPTICOS, DESINFECTANTES Y CICATRIZANTES | M36: 6.7178571 | N36: 0 | O36: 6.7178571 | P36: =O36*$V$12 -> 447.07339 | Q36: 7.7927143 | R36: VENEZUELA | S36: 46692 | U36: =+T36*Q36 -> 0
B37: 052260232 | C37: 7592090000389 | D37: MISCELANEOS | E37: BRUCEN ANTI- ACNE GEL HIDRATANTE PIELES GRASAS 120 ML | F37: 001 | G37: 18 | H37: D-PANTHENOL NIACINAMIDA | I37: BRUPHARM | J37: UNIDAD | K37: 0.16 | L37: N/A | M37: 8.3566667 | N37: 0 | O37: 8.3566667 | P37: =O37*$V$12 -> 556.13617 | Q37: 9.6937333 | R37: VENEZUELA | S37: 46569 | U37: =+T37*Q37 -> 0
B38: 022260917 | C38: 7592090000556 | D38: MISCELANEOS | E38: BRUCEN BARRA DERMO LIMPIADORA PIEL GRASA 90G | F38: 001 | G38: 44 | H38: N/A | I38: BRUPHARM | J38: UNIDAD | K38: 0.16 | L38: N/A | M38: 3.27 | N38: 0 | O38: 3.27 | P38: =O38*$V$12 -> 217.6185 | Q38: 3.7932 | R38: VENEZUELA | S38: 46327 | U38: =+T38*Q38 -> 0
B39: 052260244 | C39: 7592090000563 | D39: MISCELANEOS | E39: BRUCEN BARRA DERMO LIMPIADORA PIEL MIXTA X 90G | F39: 001 | G39: 48 | H39: N/A | I39: BRUPHARM | J39: UNIDAD | K39: 0.16 | L39: N/A | M39: 3.3 | N39: 0 | O39: 3.3 | P39: =O39*$V$12 -> 219.615 | Q39: 3.828 | R39: VENEZUELA | S39: 46327 | U39: =+T39*Q39 -> 0
B40: 052260245 | C40: 7592090000570 | D40: MISCELANEOS | E40: BRUCEN BARRA DERMO LIMPIADORA PIEL SECA 90G | F40: 001 | G40: 48 | H40: N/A | I40: BRUPHARM | J40: UNIDAD | K40: 0.16 | L40: N/A | M40: 3.2727273 | N40: 0 | O40: 3.2727273 | P40: =O40*$V$12 -> 217.8 | Q40: 3.7963636 | R40: VENEZUELA | S40: 46296 | U40: =+T40*Q40 -> 0
B41: PTBARRADERMO04 | C41: 7592090000587 | D41: MISCELANEOS | E41: BRUCEN BARRA DERMOLIMPIADORA NIÑOS | F41: 001 | G41: 24 | H41: N/A | I41: BRUPHARM | J41: UNIDAD | K41: 0.16 | L41: N/A | M41: 3.2727273 | N41: 0 | O41: 3.2727273 | P41: =O41*$V$12 -> 217.8 | Q41: 3.7963636 | R41: VENEZUELA | S41: 46296 | U41: =+T41*Q41 -> 0
B42: 052260229 | C42: 7592090000341 | D42: MISCELANEOS | E42: BRUCEN CREMA DE MANOS SPF COLAGENO 50 GR | F42: 001 | G42: 28 | H42: PROTECTOR SOLAR-COLAGENO | I42: BRUPHARM | J42: UNIDAD | K42: 0.16 | L42: PIEL Y MUCOSAS - PROTECTORES SOLARES | M42: 4.3340476 | N42: 0 | O42: 4.3340476 | P42: =O42*$V$12 -> 288.43087 | Q42: 5.0274952 | R42: VENEZUELA | S42: 46327 | U42: =+T42*Q42 -> 0
A43: PRODUCTOS TOP | B43: 052260230 | C43: 7592090000358 | D43: MISCELANEOS | E43: BRUCEN CREMA DE MANOS SPF VITAMINA E 50 GR | F43: 001 | G43: 41 | H43: PROTECTOR SOLAR-VITAMINA E | I43: BRUPHARM | J43: UNIDAD | K43: 0.16 | L43: PIEL Y MUCOSAS - PROTECTORES SOLARES | M43: 3.3666667 | N43: 0 | O43: 3.3666667 | P43: =O43*$V$12 -> 224.05167 | Q43: 3.9053333 | R43: VENEZUELA | S43: 45748 | U43: =+T43*Q43 -> 0
A44: PRODUCTOS TOP | B44: 052260243 | C44: 7592090000518 | D44: MISCELANEOS | E44: BRUCEN CREMA NUTRITIVA ACIDO HIALURONICO 1% X 80g | F44: 001 | G44: 6 | H44: ACIDO HIALURONICO | I44: BRUPHARM | J44: UNIDAD | K44: 0.16 | L44: N/A | M44: 9.3809524 | N44: 0 | O44: 9.3809524 | P44: =O44*$V$12 -> 624.30238 | Q44: 10.881905 | R44: VENEZUELA | S44: 46631 | U44: =+T44*Q44 -> 0
B45: 022260864 | C45: 7592090000037 | D45: MISCELANEOS | E45: BRUCEN CREMA NUTRITIVA Y RESTAURADORA X 80g | F45: 001 | G45: 35 | H45: PANTENOL | I45: BRUPHARM | J45: DISPLAY X6 | K45: 0.16 | L45: N/A | M45: 7.8888608 | N45: 0 | O45: 7.8888608 | P45: =O45*$V$12 -> 525.00368 | Q45: 9.1510785 | R45: VENEZUELA | S45: 46054 | U45: =+T45*Q45 -> 0
B46: 052260226 | C46: 7592090001454 | D46: MISCELANEOS | E46: BRUCEN ENJUAGUE BUCAL COOL MINT X 250ML | F46: 001 | G46: 24 | H46: N/A | I46: BRUPHARM | J46: UNIDAD | K46: 0.16 | L46: N/A | M46: 2.932619 | N46: 0 | O46: 2.932619 | P46: =O46*$V$12 -> 195.1658 | Q46: 3.4018381 | R46: VENEZUELA | S46: 46692 | U46: =+T46*Q46 -> 0
B47: 022260913 | C47: 7592090001461 | D47: MISCELANEOS | E47: BRUCEN ENJUAGUE BUCAL HIERBABUENA X 250ML | F47: 001 | G47: 12 | H47: N/A | I47: BRUPHARM | J47: UNIDAD | K47: 0.16 | L47: N/A | M47: 2.932619 | N47: 0 | O47: 2.932619 | P47: =O47*$V$12 -> 195.1658 | Q47: 3.4018381 | R47: VENEZUELA | S47: 46692 | U47: =+T47*Q47 -> 0
B48: 052260225 | C48: 7592090001447 | D48: MISCELANEOS | E48: BRUCEN ENJUAGUE BUCAL MENTA X 250ML | F48: 001 | G48: 24 | H48: N/A | I48: BRUPHARM | J48: UNIDAD | K48: 0.16 | L48: N/A | M48: 2.932619 | N48: 0 | O48: 2.932619 | P48: =O48*$V$12 -> 195.1658 | Q48: 3.4018381 | R48: VENEZUELA | S48: 46296 | U48: =+T48*Q48 -> 0
B49: 052260235 | C49: 7592090000372 | D49: MISCELANEOS | E49: BRUCEN GEL CREMA ANTIACNE 20 G | F49: 001 | G49: 18 | H49: N/A | I49: BRUPHARM | J49: UNIDAD | K49: 0.16 | L49: N/A | M49: 6.2675 | N49: 0 | O49: 6.2675 | P49: =O49*$V$12 -> 417.10213 | Q49: 7.2703 | R49: VENEZUELA | S49: 46661 | U49: =+T49*Q49 -> 0
B50: 052260237 | C50: 7592090000402 | D50: MISCELANEOS | E50: BRUCEN GEL HIDRATANTE PARA PIELES GRASAS HYDRO 120 ML | F50: 001 | G50: 13 | H50: NIACINAMIDA | I50: BRUPHARM | J50: UNIDAD | K50: 0.16 | L50: N/A | M50: 8.5513095 | N50: 0 | O50: 8.5513095 | P50: =O50*$V$12 -> 569.08965 | Q50: 9.919519 | R50: VENEZUELA | S50: 46753 | U50: =+T50*Q50 -> 0
...

Sheet STK
A1: COD | B1: PRODUCTO | C1: UNIDAD MANEJO | D1: LAB | E1: CATEG | F1: 001 | G1: 002 | H1: 003 | I1: 004 | J1: 007 | K1: 008 | L1: TOTAL | M1: COD

Sheet REF1
A1: orden | B1: CODIGO | C1: PRODUCTO | D1: alma | E1: LABORATORIO | F1: FECHA | G1: PEDIDO | H1: PRECIO UNITARIO | I1: SUB-TOTAL | J1: TOTAL | K1: FILA | L1: OPORTUNIDAD | M1: OLIMPIADAS
A2: 1 | B2: =+'LISTADO GENERAL '!B14 -> 040230007 | C2: =+'LISTADO GENERAL '!E14 -> APOSITOS KIDS BRIUTCARE (KIDS CURITAS) X 20 UND | D2: =+'LISTADO GENERAL '!F14 -> 0 | E2: =+'LISTADO GENERAL '!I14 -> BRIUTCARE | F2: =+'LISTADO GENERAL '!S14 -> 47119 | G2: =+'LISTADO GENERAL '!T14 -> 0 | H2: =+'LISTADO GENERAL '!O14 -> 1.5103545 | I2: =+H2*G2 -> 0 | J2: =IF('LISTADO GENERAL '!K14="EXENTO",'REF1'!I2,I2*1.16) -> 0 | K2: =IF(AND(G2>0,AND(L2<>$L$1,L2<>$M$1)),ROW()) -> FALSE | L2: ='LISTADO GENERAL '!A14 -> PRODUCTOS TOP
A3: 2 | B3: =+'LISTADO GENERAL '!B15 -> 000939 | C3: =+'LISTADO GENERAL '!E15 -> SULFATO FERROSO 125 MG/ML X 30 ML GOTAS | D3: =+'LISTADO GENERAL '!F15 -> 0 | E3: =+'LISTADO GENERAL '!I15 -> RJR | F3: =+'LISTADO GENERAL '!S15 -> 46174 | G3: =+'LISTADO GENERAL '!T15 -> 0 | H3: =+'LISTADO GENERAL '!O15 -> 1.5324675 | I3: =+H3*G3 -> 0 | J3: =IF('LISTADO GENERAL '!K15="EXENTO",'REF1'!I3,I3*1.16) -> 0 | K3: =IF(AND(G3>0,AND(L3<>$L$1,L3<>$M$1)),ROW()) -> FALSE | L3: ='LISTADO GENERAL '!A15 -> 0
A4: 3 | B4: =+'LISTADO GENERAL '!B16 -> 033730000 | C4: =+'LISTADO GENERAL '!E16 -> ABECAB 5/20 MG ( AMLODIPINO - OLMESARTAN) X 30 TAB | D4: =+'LISTADO GENERAL '!F16 -> 0 | E4: =+'LISTADO GENERAL '!I16 -> CAPSUVEN | F4: =+'LISTADO GENERAL '!S16 -> 46508 | G4: =+'LISTADO GENERAL '!T16 -> 0 | H4: =+'LISTADO GENERAL '!O16 -> 2.2130952 | I4: =+H4*G4 -> 0 | J4: =IF('LISTADO GENERAL '!K16="EXENTO",'REF1'!I4,I4*1.16) -> 0 | K4: =IF(AND(G4>0,AND(L4<>$L$1,L4<>$M$1)),ROW()) -> FALSE | L4: ='LISTADO GENERAL '!A16 -> MORADO DE BIENESTAR
A5: 4 | B5: =+'LISTADO GENERAL '!B17 -> 0337300023 | C5: =+'LISTADO GENERAL '!E17 -> ABECAB 5-40 mg X 30 TAB | D5: =+'LISTADO GENERAL '!F17 -> 0 | E5: =+'LISTADO GENERAL '!I17 -> CAPSUVEN | F5: =+'LISTADO GENERAL '!S17 -> 45870 | G5: =+'LISTADO GENERAL '!T17 -> 0 | H5: =+'LISTADO GENERAL '!O17 -> 5.6025974 | I5: =+H5*G5 -> 0 | J5: =IF('LISTADO GENERAL '!K17="EXENTO",'REF1'!I5,I5*1.16) -> 0 | K5: =IF(AND(G5>0,AND(L5<>$L$1,L5<>$M$1)),ROW()) -> FALSE | L5: ='LISTADO GENERAL '!A17 -> MORADO DE BIENESTAR
A6: 5 | B6: =+'LISTADO GENERAL '!B18 -> 000930 | C6: =+'LISTADO GENERAL '!E18 -> ABIDOR GOTAS 200 MG 2 ML-15 ML TUTTI FRUTTI | D6: =+'LISTADO GENERAL '!F18 -> 0 | E6: =+'LISTADO GENERAL '!I18 -> RJR | F6: =+'LISTADO GENERAL '!S18 -> 46113 | G6: =+'LISTADO GENERAL '!T18 -> 0 | H6: =+'LISTADO GENERAL '!O18 -> 0.81818182 | I6: =+H6*G6 -> 0 | J6: =IF('LISTADO GENERAL '!K18="EXENTO",'REF1'!I6,I6*1.16) -> 0 | K6: =IF(AND(G6>0,AND(L6<>$L$1,L6<>$M$1)),ROW()) -> FALSE | L6: ='LISTADO GENERAL '!A18 -> 0
A7: 6 | B7: =+'LISTADO GENERAL '!B19 -> 023690016 | C7: =+'LISTADO GENERAL '!E19 -> ABINTRA SABOR NARANJA X 27 g POLVO | D7: =+'LISTADO GENERAL '!F19 -> 0 | E7: =+'LISTADO GENERAL '!I19 -> MEGALABS | F7: =+'LISTADO GENERAL '!S19 -> 46174 | G7: =+'LISTADO GENERAL '!T19 -> 0 | H7: =+'LISTADO GENERAL '!O19 -> 6.0683544 | I7: =+H7*G7 -> 0 | J7: =IF('LISTADO GENERAL '!K19="EXENTO",'REF1'!I7,I7*1.16) -> 0 | K7: =IF(AND(G7>0,AND(L7<>$L$1,L7<>$M$1)),ROW()) -> FALSE | L7: ='LISTADO GENERAL '!A19 -> PRODUCTOS TOP
A8: 7 | B8: =+'LISTADO GENERAL '!B20 -> 021430797 | C8: =+'LISTADO GENERAL '!E20 -> ABRETIA 18MG X 10 CAP | D8: =+'LISTADO GENERAL '!F20 -> 0 | E8: =+'LISTADO GENERAL '!I20 -> MEGALABS | F8: =+'LISTADO GENERAL '!S20 -> 46539 | G8: =+'LISTADO GENERAL '!T20 -> 0 | H8: =+'LISTADO GENERAL '!O20 -> 22.825316 | I8: =+H8*G8 -> 0 | J8: =IF('LISTADO GENERAL '!K20="EXENTO",'REF1'!I8,I8*1.16) -> 0 | K8: =IF(AND(G8>0,AND(L8<>$L$1,L8<>$M$1)),ROW()) -> FALSE | L8: ='LISTADO GENERAL '!A20 -> PRODUCTOS TOP
A9: 8 | B9: =+'LISTADO GENERAL '!B21 -> 023630001 | C9: =+'LISTADO GENERAL '!E21 -> ACCUALAXAN POLVO PARA SOL.MACROGOL 3350 SOBRE X 17grs | D9: =+'LISTADO GENERAL '!F21 -> 0 | E9: =+'LISTADO GENERAL '!I21 -> GARDEN HOUSE | F9: =+'LISTADO GENERAL '!S21 -> 46054 | G9: =+'LISTADO GENERAL '!T21 -> 0 | H9: =+'LISTADO GENERAL '!O21 -> 0.59690476 | I9: =+H9*G9 -> 0 | J9: =IF('LISTADO GENERAL '!K21="EXENTO",'REF1'!I9,I9*1.16) -> 0 | K9: =IF(AND(G9>0,AND(L9<>$L$1,L9<>$M$1)),ROW()) -> FALSE | L9: ='LISTADO GENERAL '!A21 -> PRODUCTOS TOP
A10: 9 | B10: =+'LISTADO GENERAL '!B22 -> 023630000 | C10: =+'LISTADO GENERAL '!E22 -> ACCUALAXAN POLVO PARA SOL.MACROGOL 3350 X 255g PARA 15 DOSIS | D10: =+'LISTADO GENERAL '!F22 -> 0 | E10: =+'LISTADO GENERAL '!I22 -> GARDEN HOUSE | F10: =+'LISTADO GENERAL '!S22 -> 46054 | G10: =+'LISTADO GENERAL '!T22 -> 0 | H10: =+'LISTADO GENERAL '!O22 -> 3.8533333 | I10: =+H10*G10 -> 0 | J10: =IF('LISTADO GENERAL '!K22="EXENTO",'REF1'!I10,I10*1.16) -> 0 | K10: =IF(AND(G10>0,AND(L10<>$L$1,L10<>$M$1)),ROW()) -> FALSE | L10: ='LISTADO GENERAL '!A22 -> PRODUCTOS TOP
A11: 10 | B11: =+'LISTADO GENERAL '!B23 -> 021091126 | C11: =+'LISTADO GENERAL '!E23 -> ACEMUK (ACETILCISTEINA ) 200 MG X 10 TAB | D11: =+'LISTADO GENERAL '!F23 -> 0 | E11: =+'LISTADO GENERAL '!I23 -> MEYER | F11: =+'LISTADO GENERAL '!S23 -> 45809 | G11: =+'LISTADO GENERAL '!T23 -> 0 | H11: =+'LISTADO GENERAL '!O23 -> 12.691 | I11: =+H11*G11 -> 0 | J11: =IF('LISTADO GENERAL '!K23="EXENTO",'REF1'!I11,I11*1.16) -> 0 | K11: =IF(AND(G11>0,AND(L11<>$L$1,L11<>$M$1)),ROW()) -> FALSE | L11: ='LISTADO GENERAL '!A23 -> BROCHE DE ORO
A12: 11 | B12: =+'LISTADO GENERAL '!B24 -> 021181061 | C12: =+'LISTADO GENERAL '!E24 -> ACETAB 250MG X 20 TAB | D12: =+'LISTADO GENERAL '!F24 -> 0 | E12: =+'LISTADO GENERAL '!I24 -> OFTALMI | F12: =+'LISTADO GENERAL '!S24 -> 46174 | G12: =+'LISTADO GENERAL '!T24 -> 0 | H12: =+'LISTADO GENERAL '!O24 -> 12.4852 | I12: =+H12*G12 -> 0 | J12: =IF('LISTADO GENERAL '!K24="EXENTO",'REF1'!I12,I12*1.16) -> 0 | K12: =IF(AND(G12>0,AND(L12<>$L$1,L12<>$M$1)),ROW()) -> FALSE | L12: ='LISTADO GENERAL '!A24 -> BROCHE DE ORO
A13: 12 | B13: =+'LISTADO GENERAL '!B25 -> 7591616002142 | C13: =+'LISTADO GENERAL '!E25 -> ACETAFEN FORTE 180 MG / 5 ML X 120 ML JBE | D13: =+'LISTADO GENERAL '!F25 -> 0 | E13: =+'LISTADO GENERAL '!I25 -> BIOFARCO | F13: =+'LISTADO GENERAL '!S25 -> 46235 | G13: =+'LISTADO GENERAL '!T25 -> 0 | H13: =+'LISTADO GENERAL '!O25 -> 3.0467532 | I13: =+H13*G13 -> 0 | J13: =IF('LISTADO GENERAL '!K25="EXENTO",'REF1'!I13,I13*1.16) -> 0 | K13: =IF(AND(G13>0,AND(L13<>$L$1,L13<>$M$1)),ROW()) -> FALSE | L13: ='LISTADO GENERAL '!A25 -> 0
... A2196: 2195 | B2196: =+'LISTADO GENERAL '!B2208 -> 022010968 | C2196: =+'LISTADO GENERAL '!E2208 -> ZUDENINA FORTE 0,3% GEL X 30GR* | D2196: =+'LISTADO GENERAL '!F2208 -> 0 | E2196: =+'LISTADO GENERAL '!I2208 -> MEDIHEALTH | F2196: =+'LISTADO GENERAL '!S2208 -> 46296 | G2196: =+'LISTADO GENERAL '!T2208 -> 0 | H2196: =+'LISTADO GENERAL '!O2208 -> 8.5379747 | I2196: =+H2196*G2196 -> 0 | J2196: =IF('LISTADO GENERAL '!K2208="EXENTO",'REF1'!I2196,I2196*1.16) -> 0 | K2196: =IF(AND(G2196>0,AND(L2196<>$L$1,L2196<>$M$1)),ROW()) -> FALSE | L2196: ='LISTADO GENERAL '!A2208 -> 0
A2197: 2196 | B2197: =+MISCELANEOS!B14 -> 7591616000032 | C2197: =+MISCELANEOS!E14 -> ACEITE DE ALMENDRAS DULCES X 30 ML SOL | D2197: =+MISCELANEOS!F14 -> 001 | E2197: =+MISCELANEOS!I14 -> BIOFARCO | F2197: =+MISCELANEOS!S14 -> 46539 | G2197: =+MISCELANEOS!T14 -> 0 | H2197: =+MISCELANEOS!O14 -> 2.1118182 | I2197: =+H2197*G2197 -> 0 | J2197: =IF('LISTADO GENERAL '!K2209="EXENTO",'REF1'!I2197,I2197*1.16) -> 0 | K2197: =IF(AND(G2197>0,AND(L2197<>$L$1,L2197<>$M$1)),ROW()) -> FALSE | L2197: ='LISTADO GENERAL '!A2209 -> 0
A2198: 2197 | B2198: =+MISCELANEOS!B15 -> 7591616000056 | C2198: =+MISCELANEOS!E15 -> ACEITE DE COCO X 30 ML SOL | D2198: =+MISCELANEOS!F15 -> 001 | E2198: =+MISCELANEOS!I15 -> BIOFARCO | F2198: =+MISCELANEOS!S15 -> 46661 | G2198: =+MISCELANEOS!T15 -> 0 | H2198: =+MISCELANEOS!O15 -> 2.987013 | I2198: =+H2198*G2198 -> 0 | J2198: =IF('LISTADO GENERAL '!K2210="EXENTO",'REF1'!I2198,I2198*1.16) -> 0 | K2198: =IF(AND(G2198>0,AND(L2198<>$L$1,L2198<>$M$1)),ROW()) -> FALSE | L2198: ='LISTADO GENERAL '!A2210 -> 0
A2199: 2198 | B2199: =+MISCELANEOS!B16 -> 7591616000131 | C2199: =+MISCELANEOS!E16 -> ACEITE DE RICINO X 30 ML SOL | D2199: =+MISCELANEOS!F16 -> 001 | E2199: =+MISCELANEOS!I16 -> BIOFARCO | F2199: =+MISCELANEOS!S16 -> 46631 | G2199: =+MISCELANEOS!T16 -> 0 | H2199: =+MISCELANEOS!O16 -> 2.8701299 | I2199: =+H2199*G2199 -> 0 | J2199: =IF('LISTADO GENERAL '!K2211="EXENTO",'REF1'!I2199,I2199*1.16) -> 0 | K2199: =IF(AND(G2199>0,AND(L2199<>$L$1,L2199<>$M$1)),ROW()) -> FALSE | L2199: ='LISTADO GENERAL '!A2211 -> 0
A2200: 2199 | B2200: =+MISCELANEOS!B17 -> 052670024 | C2200: =+MISCELANEOS!E17 -> ACEITE MINERAL 30 ML | D2200: =+MISCELANEOS!F17 -> 001 | E2200: =+MISCELANEOS!I17 -> LYA | F2200: =+MISCELANEOS!S17 -> 45931 | G2200: =+MISCELANEOS!T17 -> 0 | H2200: =+MISCELANEOS!O17 -> 2.5222222 | I2200: =+H2200*G2200 -> 0 | J2200: =IF('LISTADO GENERAL '!K2212="EXENTO",'REF1'!I2200,I2200*1.16) -> 0 | K2200: =IF(AND(G2200>0,AND(L2200<>$L$1,L2200<>$M$1)),ROW()) -> FALSE | L2200: ='LISTADO GENERAL '!A2212 -> 0
