Workbook
Name BASE: #REF!
Name consig: #REF!
Name CONSIGNACION: #REF!
Name mm: #REF!
Name STK: STK!$1:$1048576
Name UNIPHARMA: #REF!

Sheet Hoja1
A1: J-310958319
F14: MAYO 2026
A15: LISTA DE PRECIOS GENERAL
A16: AMPOLLAS
A17: DESCRIPCION | B17: ALMACEN | C17: PRINCIPIO ACTIVO | D17: LABORATORIO | E17: FECHA | F17: PRECIO | G17: PEDIDO | H17: TOTAL $
A18: ATROPINA SULFATO 1mg/1ml ( I.V / I. M / SC ) AMPOLLA | B18: 100 | C18: ATROPINA | D18: BIOSANO | E18: 46600 | F18: 0.94 | H18: =G18*F18 -> 0
A19: KETOPROFENO AMP 100 MG 2 ML IM/IV BIOSANO | B19: 100 | C19: KETOPROFENO | D19: BIOSANO | E19: 46357 | F19: 1.67 | H19: =G19*F19 -> 0
A20: AMIKACINA 100 MG/2ML ( I.V / I. M) AMPOLLA | B20: 100 | C20: AMIKACINA | D20: BIOSANO | E20: 46722 | F20: 1.64 | H20: =G20*F20 -> 0
A21: AMIODARONA CLORHIDRATO 150MG / 3 ML ( I.V ) AMPOLLA | B21: 50 | C21: AMIODARONA | D21: BIOSANO | E21: 46357 | F21: 1.35 | H21: =G21*F21 -> 0
A22: DIPIRONA AMP 1 G 2 ML VITALIS | B22: 100 | C22: DIPIRONA | D22: VITALIS | E22: 46997 | F22: 0.72 | H22: =G22*F22 -> 0
A23: METOCLOPRAMIDA AMP 10 MG 2 ML VITALIS | B23: 100 | C23: METOCLOPRAMIDA | D23: VITALIS | E23: 47270 | F23: 0.87 | H23: =G23*F23 -> 0
F24: 0 | H24: =G24*F24 -> 0
A25: ACICLOVIR AMP 250 MG UNI VITALIS (E) | B25: 34 | C25: ACICLOVIR | D25: VITALIS | E25: 47102 | F25: 15.142857 | H25: =G25*F25 -> 0
A26: ACICLOVIR AMP 250 MG UNI VITALIS (E) | B26: 50 | C26: ACICLOVIR | D26: VITALIS | E26: 46962 | F26: 15.142857 | H26: =G26*F26 -> 0
A27: ACIDO ACETILSALICILICO TAB 81 MG CJ X 30 KMPLUS (E) | B27: 10 | C27: ACIDO | D27: KMPLUS | E27: 46843 | F27: 3.2 | H27: =G27*F27 -> 0
A28: ACIDO FOLICO AMP 10 MG 2 ML BIOGLASS (E) | B28: 184 | C28: ACIDO | D28: BIOGLASS | E28: 46599 | F28: 4.7 | H28: =G28*F28 -> 0
A29: ACIDO FOLICO GOTAS 10 MG/ML 15 ML BIO DE VENEZUELA (E) | B29: 1 | C29: ACIDO | D29: VENEZUELA | E29: 46203 | F29: 5.7142857 | H29: =G29*F29 -> 0
A30: ACIDO TRANEXAMICO AMP 500 MG 5 ML MEDICARE (E) | B30: 415 | C30: ACIDO | D30: MEDICARE | E30: 47057 | F30: 2.6285714 | H30: =G30*F30 -> 0
A31: ACIDO TRANEXAMICO AMP 500 MG 5 ML VITALIS (E) | B31: 300 | C31: ACIDO | D31: VITALIS | E31: 46786 | F31: 8.1 | H31: =G31*F31 -> 0
A32: ADRENALINA AMP 1 MG 1 ML ADN (E) | B32: 192 | C32: ADRENALINA | D32: ADN | E32: 46568 | F32: 1.7142857 | H32: =G32*F32 -> 0
A33: ADRENALINA AMP 1 MG 1 ML BIOSANO (E) | B33: 385 | C33: ADRENALINA | D33: BIOSANO | E33: 46691 | F33: 1.6 | H33: =G33*F33 -> 0
A34: ADRENALINA AMP 1 MG 1 ML MEDICARE (E) | B34: 218 | C34: ADRENALINA | D34: MEDICARE | E34: 47057 | F34: 1 | H34: =G34*F34 -> 0
A35: ALBUMINA HUMANA AMP 20 % FCO 50 ML BIOPHARMA (E) | B35: 3 | C35: ALBUMINA | D35: BIOPHARMA | E35: 47118 | F35: 220.92857 | H35: =G35*F35 -> 0
A36: ALCOHOL ISOPROPILICO SOL 70 % FCO 240 ML UNIPHARMA (E) | B36: 83 | C36: ALCOHOL | D36: UNIPHARMA | E36: 46411 | F36: 2.7 | H36: =G36*F36 -> 0
... A272: VITAMINA K1 AMP 10 MG 1 ML IV/IM ALFA (E) | B272: 359 | C272: VITAMINA | D272: ALFA | E272: 46811 | F272: 2.1428571 | H272: =G272*F272 -> 0
G273: TOTAL = | H273: =SUM(H18:H272) -> 0
A274: LISTA DE PRECIOS GENERAL
A275: TABLETERIA
A276: DESCRIPCION | B276: ALMACEN | C276: PINCIPIO ACTIVO | D276: LABORATORIO | E276: FECHA | F276: PRECIO | G276: PEDIDO | H276: TOTAL $
A277: ABRETIA ( ATOMOXETINA ) 10 MG X 10 CAP ( MEGALABS ) | B277: 1 | C277: ABRETIA | D277: NOW | E277: 47798 | F277: 30.514286 | H277: =G277*F277 -> 0
A278: ABRETIA ( ATOMOXETINA ) 18 MG X 10 CAP ( MEGALABS ) | B278: 1 | C278: ABRETIA | D278: MEGALABS | E278: 47150 | F278: 24.042857 | H278: =G278*F278 -> 0
A279: ABRETIA ( ATOMOXETINA ) 25 MG X 20 CAP ( MEGALABS ) | B279: 24 | C279: ABRETIA | D279: MEGALABS | E279: 46964 | F279: 35.714286 | H279: =G279*F279 -> 0
A280: ACALIX ( DILTIAZEM ) 60 MG X 30 TAB ( VARGAS ) | B280: 24 | C280: ACALIX | D280: MEGALABS | E280: 47207 | F280: 64.285714 | H280: =G280*F280 -> 0
A281: ACEITE DE CASTOR X 30 ML ( BIOFARCO ) | B281: 1 | C281: ACEITE DE CASTOR | D281: VARGAS | E281: 46660 | F281: 12.900429 | H281: =G281*F281 -> 0
A282: ACEMUK ( ACETILCISTEINA ) 600 MG X 10 COMP EFERVECENTES ( SIEGFRIED ) | B282: 12 | C282: ACEMUK | D282: BIOFARCO | E282: 47177 | F282: 6.5 | H282: =G282*F282 -> 0
A283: ACETAB ( ACETAZOLAMIDA ) 250 MG X 20 TAB ( OFTALMI ) | B283: 1 | C283: ACETAB | D283: SIEGFRIED | E283: 46568 | F283: 33.342857 | H283: =G283*F283 -> 0
A284: ACETACLOR ( ACETAMINOFEN ) 125 MG-0.5 MG / 5ML JARABE X 120 ML ( BIOFARCO ) | B284: 65 | C284: ACETACLOR | D284: OFTALMI | E284: 46646 | F284: 19.3 | H284: =G284*F284 -> 0
A285: ACETAFEN FORTE ( ACETAMINOFEN ) 180 MG / 5 ML X 120 ML USO PED ( BIOFARCO ) | B285: 1 | C285: ACETAFEN | D285: BIOFARCO | E285: 46660 | F285: 4 | H285: =G285*F285 -> 0
A286: ACETAMINOFEN ( PARACETAMOL ) 500 MG X 10 TABLETAS ( ZAKIMED ) | B286: 1 | C286: ACETAMINOFEN | D286: BIOFARCO | E286: 46507 | F286: 3.9285714 | H286: =G286*F286 -> 0
A287: ACETAMINOFEN 100 MG / ML X 15 ML SOLUCION GOTAS PED ( QUIM-FAR) | B287: 300 | C287: ACETAMINOFEN | D287: ZAKIMED | E287: 46537 | F287: 0.65714286 | H287: =G287*F287 -> 0
...

Sheet Hoja3

Sheet Hoja2

Sheet Hoja4

Sheet STK
A1: COD | B1: PRODUCTO | C1: UNIDAD MANEJO | D1: LAB | E1: CATEG | F1: 001 | G1: 002 | H1: 003 | I1: 004 | J1: 007 | K1: 008 | L1: TOTAL | M1: COD
A2: 010020223 | B2: SOLUCION RINGERLACTATO X 500ml | C2: UNIDAD | D2: ACULIFE | E2: HOSPITALARIO | F2: 0 | G2: 0 | H2: 0 | I2: 0 | J2: 0 | K2: 0 | L2: =F2+G2+H2+J2 -> 0
A3: 010040000 | B3: DICLOFENACO 75mg/3ml X 2 AMPOLLAS | C3: UNIDAD | D3: ALPHARMA | E3: HOSPITALARIO | F3: 0 | G3: 0 | H3: 0 | I3: 0 | J3: 8 | K3: 6 | L3: =F3+G3+H3+J3 -> 8
A4: 010050080 | B4: CYTRIAX (CEFTRIAXONA) 1gr AMP X 1IV/IM | C4: UNIDAD | D4: ALESS | E4: HOSPITALARIO | F4: 9 | G4: 0 | H4: 0 | I4: 40 | J4: 0 | K4: 0 | L4: =F4+G4+H4+J4 -> 9
A5: 010050132 | B5: HIDROCORTISONA 100mg AMP | C5: UNIDAD | D5: ALESS | E5: HOSPITALARIO | F5: 0 | G5: 0 | H5: 0 | I5: 15 | J5: 0 | K5: 0 | L5: =F5+G5+H5+J5 -> 0
A6: 010050278 | B6: OMEFLUX (OMEPRAZOL) 40mg X1 IV AMP | C6: UNIDAD | D6: ALESS | E6: HOSPITALARIO | F6: 20 | G6: 0 | H6: 0 | I6: 0 | J6: 0 | K6: 0 | L6: =F6+G6+H6+J6 -> 20
A7: 010050279 | B7: LIDOCAINA AL 2% 30ml X 1 AMP INY | C7: UNIDAD | D7: ALESS | E7: HOSPITALARIO | F7: 10 | G7: 0 | H7: 0 | I7: 98 | J7: 0 | K7: 0 | L7: =F7+G7+H7+J7 -> 10
A8: 010050280 | B8: MESPEN (MEROPENEM) 1gr AMP | C8: UNIDAD | D8: ALESS | E8: HOSPITALARIO | F8: 0 | G8: 0 | H8: 0 | I8: 12 | J8: 0 | K8: 0 | L8: =F8+G8+H8+J8 -> 0
A9: 010050281 | B9: PENASTIM (IMIPENEM-CILASTATINA) 500mg-500MG X1 I.V | C9: UNIDAD | D9: ALESS | E9: HOSPITALARIO | F9: 159 | G9: 0 | H9: 0 | I9: 34 | J9: 0 | K9: 0 | L9: =F9+G9+H9+J9 -> 159
A10: 010050282 | B10: VANCINA 500MG X 1 AMP IV | C10: UNIDAD | D10: ALESS | E10: HOSPITALARIO | F10: 0 | G10: 0 | H10: 0 | I10: 0 | J10: 0 | K10: 0 | L10: =F10+G10+H10+J10 -> 0
A11: 0100510281 | B11: SULXIM (CEFOPERAZONA-SULBACTAM) 1G-0.5X 1 AMP | C11: UNIDAD | D11: ALESS | E11: HOSPITALARIO | F11: 0 | G11: 0 | H11: 0 | I11: 9 | J11: 0 | K11: 0 | L11: =F11+G11+H11+J11 -> 0
A12: 0100510282 | B12: XANEXTRA (ACIDO TRANEXAMICO) 500mg/5ml X 1 AMP | C12: UNIDAD | D12: ALESS | E12: HOSPITALARIO | F12: 0 | G12: 0 | H12: 0 | I12: 0 | J12: 0 | K12: 0 | L12: =F12+G12+H12+J12 -> 0
A13: 0100510283 | B13: TIOCOLCHICOSIDO 4mg/2mg X 2 amp | C13: UNIDAD | D13: ALESS | E13: HOSPITALARIO | F13: 288 | G13: 0 | H13: 0 | I13: 224 | J13: 0 | K13: 0 | L13: =F13+G13+H13+J13 -> 288
... A4795: 9993440002 | B4795: BATERIA 9V ALKALINE | C4795: UNIDAD | D4795: TOSHIBA | E4795: MISCELANEOS | F4795: 0 | G4795: 0 | H4795: 0 | I4795: 0 | J4795: 24 | K4795: 0 | L4795: =F4795+G4795+H4795+J4795 -> 24

Sheet REF1
A1: orden | B1: CODIGO | C1: PRODUCTO | D1: alma | E1: LABORATORIO | F1: FECHA | G1: PEDIDO | H1: PRECIO UNITARIO | I1: SUB-TOTAL | J1: TOTAL | K1: FILA
A2: 1 | B2: =+#REF! -> #REF! | C2: =+#REF! -> #REF! | D2: =+#REF! -> #REF! | E2: =+#REF! -> #REF! | F2: =+#REF! -> #REF! | G2: =+#REF! -> #REF! | H2: =+#REF! -> #REF! | I2: =+H2*G2 -> #REF! | J2: =IF(#REF!="EXENTO",'REF1'!I2,I2*1.16) -> #REF! | K2: =IF(G2>0,ROW()) -> #REF!
A3: 2 | B3: =+#REF! -> #REF! | C3: =+#REF! -> #REF! | D3: =+#REF! -> #REF! | E3: =+#REF! -> #REF! | F3: =+#REF! -> #REF! | G3: =+#REF! -> #REF! | H3: =+#REF! -> #REF! | I3: =+H3*G3 -> #REF! | J3: =IF(#REF!="EXENTO",'REF1'!I3,I3*1.16) -> #REF! | K3: =IF(G3>0,ROW()) -> #REF!
A4: 3 | B4: =+#REF! -> #REF! | C4: =+#REF! -> #REF! | D4: =+#REF! -> #REF! | E4: =+#REF! -> #REF! | F4: =+#REF! -> #REF! | G4: =+#REF! -> #REF! | H4: =+#REF! -> #REF! | I4: =+H4*G4 -> #REF! | J4: =IF(#REF!="EXENTO",'REF1'!I4,I4*1.16) -> #REF! | K4: =IF(G4>0,ROW()) -> #REF!
A5: 4 | B5: =+#REF! -> #REF! | C5: =+#REF! -> #REF! | D5: =+#REF! -> #REF! | E5: =+#REF! -> #REF! | F5: =+#REF! -> #REF! | G5: =+#REF! -> #REF! | H5: =+#REF! -> #REF! | I5: =+H5*G5 -> #REF! | J5: =IF(#REF!="EXENTO",'REF1'!I5,I5*1.16) -> #REF! | K5: =IF(G5>0,ROW()) -> #REF!
A6: 5 | B6: =+#REF! -> #REF! | C6: =+#REF! -> #REF! | D6: =+#REF! -> #REF! | E6: =+#REF! -> #REF! | F6: =+#REF! -> #REF! | G6: =+#REF! -> #REF! | H6: =+#REF! -> #REF! | I6: =+H6*G6 -> #REF! | J6: =IF(#REF!="EXENTO",'REF1'!I6,I6*1.16) -> #REF! | K6: =IF(G6>0,ROW()) -> #REF!
A7: 6 | B7: =+#REF! -> #REF! | C7: =+#REF! -> #REF! | D7: =+#REF! -> #REF! | E7: =+#REF! -> #REF! | F7: =+#REF! -> #REF! | G7: =+#REF! -> #REF! | H7: =+#REF! -> #REF! | I7: =+H7*G7 -> #REF! | J7: =IF(#REF!="EXENTO",'REF1'!I7,I7*1.16) -> #REF! | K7: =IF(G7>0,ROW()) -> #REF!
A8: 7 | B8: =+#REF! -> #REF! | C8: =+#REF! -> #REF! | D8: =+#REF! -> #REF! | E8: =+#REF! -> #REF! | F8: =+#REF! -> #REF! | G8: =+#REF! -> #REF! | H8: =+#REF! -> #REF! | I8: =+H8*G8 -> #REF! | J8: =IF(#REF!="EXENTO",'REF1'!I8,I8*1.16) -> #REF! | K8: =IF(G8>0,ROW()) -> #REF!
A9: 8 | B9: =+#REF! -> #REF! | C9: =+#REF! -> #REF! | D9: =+#REF! -> #REF! | E9: =+#REF! -> #REF! | F9: =+#REF! -> #REF! | G9: =+#REF! -> #REF! | H9: =+#REF! -> #REF! | I9: =+H9*G9 -> #REF! | J9: =IF(#REF!="EXENTO",'REF1'!I9,I9*1.16) -> #REF! | K9: =IF(G9>0,ROW()) -> #REF!
A10: 9 | B10: =+#REF! -> #REF! | C10: =+#REF! -> #REF! | D10: =+#REF! -> #REF! | E10: =+#REF! -> #REF! | F10: =+#REF! -> #REF! | G10: =+#REF! -> #REF! | H10: =+#REF! -> #REF! | I10: =+H10*G10 -> #REF! | J10: =IF(#REF!="EXENTO",'REF1'!I10,I10*1.16) -> #REF! | K10: =IF(G10>0,ROW()) -> #REF!
A11: 10 | B11: =+#REF! -> #REF! | C11: =+#REF! -> #REF! | D11: =+#REF! -> #REF! | E11: =+#REF! -> #REF! | F11: =+#REF! -> #REF! | G11: =+#REF! -> #REF! | H11: =+#REF! -> #REF! | I11: =+H11*G11 -> #REF! | J11: =IF(#REF!="EXENTO",'REF1'!I11,I11*1.16) -> #REF! | K11: =IF(G11>0,ROW()) -> #REF!
A12: 11 | B12: =+#REF! -> #REF! | C12: =+#REF! -> #REF! | D12: =+#REF! -> #REF! | E12: =+#REF! -> #REF! | F12: =+#REF! -> #REF! | G12: =+#REF! -> #REF! | H12: =+#REF! -> #REF! | I12: =+H12*G12 -> #REF! | J12: =IF(#REF!="EXENTO",'REF1'!I12,I12*1.16) -> #REF! | K12: =IF(G12>0,ROW()) -> #REF!
A13: 12 | B13: =+#REF! -> #REF! | C13: =+#REF! -> #REF! | D13: =+#REF! -> #REF! | E13: =+#REF! -> #REF! | F13: =+#REF! -> #REF! | G13: =+#REF! -> #REF! | H13: =+#REF! -> #REF! | I13: =+H13*G13 -> #REF! | J13: =IF(#REF!="EXENTO",'REF1'!I13,I13*1.16) -> #REF! | K13: =IF(G13>0,ROW()) -> #REF!
... A2122: 2121 | B2122: =+#REF! -> #REF! | C2122: =+#REF! -> #REF! | D2122: =+#REF! -> #REF! | E2122: =+#REF! -> #REF! | F2122: =+#REF! -> #REF! | G2122: =+#REF! -> #REF! | H2122: =+#REF! -> #REF! | I2122: =+H2122*G2122 -> #REF! | J2122: =IF(#REF!="EXENTO",'REF1'!I2122,I2122*1.16) -> #REF! | K2122: =IF(G2122>0,ROW()) -> #REF!
